Workbook

Sheet Al Bundy
B1: Inferential statistics. Confidence intervals
B2: Al Bundy's shoe shop
B4: InvoiceNo | C4: Date | D4: Country | E4: ProductID | F4: Shop | G4: Gender | H4: Size (US) | I4: Size (Europe) | J4: Size (UK) | K4: UnitPrice | L4: Discount | N4: Month | O4: SalePrice
B5: 52389 | C5: 41640.046 | D5: United Kingdom | E5: 2152 | F5: UK2 | G5: Male | H5: 11 | I5: =IF(G5="Male",VLOOKUP(H5,'Shoe size conversion table'!$B$6:$D$22,2),VLOOKUP(H5,'Shoe size conversion table'!$J$6:$L$22,2)) -> 44 | J5: =IF(G5="Male",VLOOKUP(H5,'Shoe size conversion table'!$B$6:$D$22,3),VLOOKUP(H5,'Shoe size conversion table'!$J$6:$L$22,3)) -> 10.5 | K5: 159 | L5: 0 | M5: =YEAR(C5) -> 2014 | N5: =MONTH(C5:C14971) -> 1 | O5: =K5*(1-L5) -> 159
B6: 52390 | C6: 41640.156 | D6: United States | E6: 2230 | F6: US15 | G6: Male | H6: 11.5 | I6: =IF(G6="Male",VLOOKUP(H6,'Shoe size conversion table'!$B$6:$D$22,2),VLOOKUP(H6,'Shoe size conversion table'!$J$6:$L$22,2)) -> 44-45 | J6: =IF(G6="Male",VLOOKUP(H6,'Shoe size conversion table'!$B$6:$D$22,3),VLOOKUP(H6,'Shoe size conversion table'!$J$6:$L$22,3)) -> 11 | K6: 199 | L6: 0.2 | M6: =YEAR(C6) -> 2014 | N6: =MONTH(C6:C14973) -> 1 | O6: =K6*(1-L6) -> 159.2
B7: 52391 | C7: 41640.376 | D7: Canada | E7: 2160 | F7: CAN7 | G7: Male | H7: 9.5 | I7: =IF(G7="Male",VLOOKUP(H7,'Shoe size conversion table'!$B$6:$D$22,2),VLOOKUP(H7,'Shoe size conversion table'!$J$6:$L$22,2)) -> 42-43 | J7: =IF(G7="Male",VLOOKUP(H7,'Shoe size conversion table'!$B$6:$D$22,3),VLOOKUP(H7,'Shoe size conversion table'!$J$6:$L$22,3)) -> 9 | K7: 149 | L7: 0.2 | M7: =YEAR(C7) -> 2014 | N7: =MONTH(C7:C14974) -> 1 | O7: =K7*(1-L7) -> 119.2
B8: 52392 | C8: 41640.386 | D8: United States | E8: 2234 | F8: US6 | G8: Female | H8: 9.5 | I8: =IF(G8="Male",VLOOKUP(H8,'Shoe size conversion table'!$B$6:$D$22,2),VLOOKUP(H8,'Shoe size conversion table'!$J$6:$L$22,2)) -> 40 | J8: =IF(G8="Male",VLOOKUP(H8,'Shoe size conversion table'!$B$6:$D$22,3),VLOOKUP(H8,'Shoe size conversion table'!$J$6:$L$22,3)) -> 7.5 | K8: 159 | L8: 0 | M8: =YEAR(C8) -> 2014 | N8: =MONTH(C8:C14975) -> 1 | O8: =K8*(1-L8) -> 159
B9: 52393 | C9: 41640.566 | D9: United Kingdom | E9: 2222 | F9: UK4 | G9: Female | H9: 9 | I9: =IF(G9="Male",VLOOKUP(H9,'Shoe size conversion table'!$B$6:$D$22,2),VLOOKUP(H9,'Shoe size conversion table'!$J$6:$L$22,2)) -> 39-40 | J9: =IF(G9="Male",VLOOKUP(H9,'Shoe size conversion table'!$B$6:$D$22,3),VLOOKUP(H9,'Shoe size conversion table'!$J$6:$L$22,3)) -> 7 | K9: 159 | L9: 0 | M9: =YEAR(C9) -> 2014 | N9: =MONTH(C9:C14976) -> 1 | O9: =K9*(1-L9) -> 159
B10: 52394 | C10: 41640.666 | D10: United States | E10: 2173 | F10: US15 | G10: Male | H10: 10.5 | I10: =IF(G10="Male",VLOOKUP(H10,'Shoe size conversion table'!$B$6:$D$22,2),VLOOKUP(H10,'Shoe size conversion table'!$J$6:$L$22,2)) -> 43-44 | J10: =IF(G10="Male",VLOOKUP(H10,'Shoe size conversion table'!$B$6:$D$22,3),VLOOKUP(H10,'Shoe size conversion table'!$J$6:$L$22,3)) -> 10 | K10: 159 | L10: 0 | M10: =YEAR(C10) -> 2014 | N10: =MONTH(C10:C14977) -> 1 | O10: =K10*(1-L10) -> 159
B11: 52395 | C11: 41641.046 | D11: Germany | E11: 2200 | F11: GER2 | G11: Female | H11: 9 | I11: =IF(G11="Male",VLOOKUP(H11,'Shoe size conversion table'!$B$6:$D$22,2),VLOOKUP(H11,'Shoe size conversion table'!$J$6:$L$22,2)) -> 39-40 | J11: =IF(G11="Male",VLOOKUP(H11,'Shoe size conversion table'!$B$6:$D$22,3),VLOOKUP(H11,'Shoe size conversion table'!$J$6:$L$22,3)) -> 7 | K11: 179 | L11: 0 | M11: =YEAR(C11) -> 2014 | N11: =MONTH(C11:C14978) -> 1 | O11: =K11*(1-L11) -> 179
B12: 52396 | C12: 41641.376 | D12: Canada | E12: 2238 | F12: CAN5 | G12: Male | H12: 10 | I12: =IF(G12="Male",VLOOKUP(H12,'Shoe size conversion table'!$B$6:$D$22,2),VLOOKUP(H12,'Shoe size conversion table'!$J$6:$L$22,2)) -> 43 | J12: =IF(G12="Male",VLOOKUP(H12,'Shoe size conversion table'!$B$6:$D$22,3),VLOOKUP(H12,'Shoe size conversion table'!$J$6:$L$22,3)) -> 9.5 | K12: 169 | L12: 0 | M12: =YEAR(C12) -> 2014 | N12: =MONTH(C12:C14979) -> 1 | O12: =K12*(1-L12) -> 169
B13: 52397 | C13: 41641.386 | D13: United States | E13: 2191 | F13: US13 | G13: Male | H13: 10.5 | I13: =IF(G13="Male",VLOOKUP(H13,'Shoe size conversion table'!$B$6:$D$22,2),VLOOKUP(H13,'Shoe size conversion table'!$J$6:$L$22,2)) -> 43-44 | J13: =IF(G13="Male",VLOOKUP(H13,'Shoe size conversion table'!$B$6:$D$22,3),VLOOKUP(H13,'Shoe size conversion table'!$J$6:$L$22,3)) -> 10 | K13: 139 | L13: 0 | M13: =YEAR(C13) -> 2014 | N13: =MONTH(C13:C14980) -> 1 | O13: =K13*(1-L13) -> 139
B14: 52398 | C14: 41641.566 | D14: United Kingdom | E14: 2237 | F14: UK1 | G14: Female | H14: 9 | I14: =IF(G14="Male",VLOOKUP(H14,'Shoe size conversion table'!$B$6:$D$22,2),VLOOKUP(H14,'Shoe size conversion table'!$J$6:$L$22,2)) -> 39-40 | J14: =IF(G14="Male",VLOOKUP(H14,'Shoe size conversion table'!$B$6:$D$22,3),VLOOKUP(H14,'Shoe size conversion table'!$J$6:$L$22,3)) -> 7 | K14: 149 | L14: 0 | M14: =YEAR(C14) -> 2014 | N14: =MONTH(C14:C14981) -> 1 | O14: =K14*(1-L14) -> 149
B15: 52399 | C15: 41641.596 | D15: United States | E15: 2197 | F15: US1 | G15: Male | H15: 10 | I15: =IF(G15="Male",VLOOKUP(H15,'Shoe size conversion table'!$B$6:$D$22,2),VLOOKUP(H15,'Shoe size conversion table'!$J$6:$L$22,2)) -> 43 | J15: =IF(G15="Male",VLOOKUP(H15,'Shoe size conversion table'!$B$6:$D$22,3),VLOOKUP(H15,'Shoe size conversion table'!$J$6:$L$22,3)) -> 9.5 | K15: 129 | L15: 0 | M15: =YEAR(C15) -> 2014 | N15: =MONTH(C15:C14982) -> 1 | O15: =K15*(1-L15) -> 129
B16: 52399 | C16: 41641.596 | D16: United States | E16: 2213 | F16: US11 | G16: Female | H16: 9.5 | I16: =IF(G16="Male",VLOOKUP(H16,'Shoe size conversion table'!$B$6:$D$22,2),VLOOKUP(H16,'Shoe size conversion table'!$J$6:$L$22,2)) -> 40 | J16: =IF(G16="Male",VLOOKUP(H16,'Shoe size conversion table'!$B$6:$D$22,3),VLOOKUP(H16,'Shoe size conversion table'!$J$6:$L$22,3)) -> 7.5 | K16: 169 | L16: 0.1 | M16: =YEAR(C16) -> 2014 | N16: =MONTH(C16:C14983) -> 1 | O16: =K16*(1-L16) -> 152.1
B17: 52399 | C17: 41641.596 | D17: United States | E17: 2206 | F17: US2 | G17: Female | H17: 9.5 | I17: =IF(G17="Male",VLOOKUP(H17,'Shoe size conversion table'!$B$6:$D$22,2),VLOOKUP(H17,'Shoe size conversion table'!$J$6:$L$22,2)) -> 40 | J17: =IF(G17="Male",VLOOKUP(H17,'Shoe size conversion table'!$B$6:$D$22,3),VLOOKUP(H17,'Shoe size conversion table'!$J$6:$L$22,3)) -> 7.5 | K17: 139 | L17: 0 | M17: =YEAR(C17) -> 2014 | N17: =MONTH(C17:C14984) -> 1 | O17: =K17*(1-L17) -> 139
... B14971: 65777 | C14971: 42735.786 | D14971: Germany | E14971: 2156 | F14971: GER1 | G14971: Female | H14971: 6.5 | I14971: =IF(G14971="Male",VLOOKUP(H14971,'Shoe size conversion table'!$B$6:$D$22,2),VLOOKUP(H14971,'Shoe size conversion table'!$J$6:$L$22,2)) -> 37 | J14971: =IF(G14971="Male",VLOOKUP(H14971,'Shoe size conversion table'!$B$6:$D$22,3),VLOOKUP(H14971,'Shoe size conversion table'!$J$6:$L$22,3)) -> 4.5 | K14971: 139 | L14971: 0.1 | M14971: =YEAR(C14971) -> 2016 | N14971: =MONTH(C14971:C29938) -> 12 | O14971: =K14971*(1-L14971) -> 125.1
C14973: Jan | D14973: Germany | E14973: 2156 | F14973: GER1 | G14973: Female | H14973: 4.5 | I14973: =IF(G14973="Male",VLOOKUP(H14973,'Shoe size conversion table'!$B$6:$D$22,2),VLOOKUP(H14973,'Shoe size conversion table'!$J$6:$L$22,2)) -> 35 | J14973: =IF(G14973="Male",VLOOKUP(H14973,'Shoe size conversion table'!$B$6:$D$22,3),VLOOKUP(H14973,'Shoe size conversion table'!$J$6:$L$22,3)) -> 2.5 | K14973: 179 | L14973: 0 | M14973: =YEAR(C14973) -> #VALUE! | N14973: =MONTH(C14973:C29939) -> #VALUE! | O14973: =K14973*(1-L14973) -> 179
C14974: Feb | D14974: Germany | E14974: 2156 | F14974: GER1 | G14974: Female | H14974: 4.5 | I14974: =IF(G14974="Male",VLOOKUP(H14974,'Shoe size conversion table'!$B$6:$D$22,2),VLOOKUP(H14974,'Shoe size conversion table'!$J$6:$L$22,2)) -> 35 | J14974: =IF(G14974="Male",VLOOKUP(H14974,'Shoe size conversion table'!$B$6:$D$22,3),VLOOKUP(H14974,'Shoe size conversion table'!$J$6:$L$22,3)) -> 2.5 | K14974: 139 | L14974: 0.1 | M14974: =YEAR(C14974) -> #VALUE! | N14974: =MONTH(C14974:C29940) -> #VALUE! | O14974: =K14974*(1-L14974) -> 125.1
C14975: March | D14975: Germany | E14975: 2156 | F14975: GER1 | G14975: Female | H14975: 4.5 | I14975: =IF(G14975="Male",VLOOKUP(H14975,'Shoe size conversion table'!$B$6:$D$22,2),VLOOKUP(H14975,'Shoe size conversion table'!$J$6:$L$22,2)) -> 35 | J14975: =IF(G14975="Male",VLOOKUP(H14975,'Shoe size conversion table'!$B$6:$D$22,3),VLOOKUP(H14975,'Shoe size conversion table'!$J$6:$L$22,3)) -> 2.5 | K14975: 139 | L14975: 0.1 | M14975: =YEAR(C14975) -> #VALUE! | N14975: =MONTH(C14975:C29941) -> #VALUE! | O14975: =K14975*(1-L14975) -> 125.1
C14976: August | D14976: Germany | E14976: 2156 | F14976: GER1 | G14976: Female | H14976: 4.5 | I14976: =IF(G14976="Male",VLOOKUP(H14976,'Shoe size conversion table'!$B$6:$D$22,2),VLOOKUP(H14976,'Shoe size conversion table'!$J$6:$L$22,2)) -> 35 | J14976: =IF(G14976="Male",VLOOKUP(H14976,'Shoe size conversion table'!$B$6:$D$22,3),VLOOKUP(H14976,'Shoe size conversion table'!$J$6:$L$22,3)) -> 2.5 | K14976: 139 | L14976: 0.1 | M14976: =YEAR(C14976) -> #VALUE! | N14976: =MONTH(C14976:C29942) -> #VALUE! | O14976: =K14976*(1-L14976) -> 125.1
D14977: Germany | E14977: 2156 | F14977: GER1 | G14977: Female | H14977: 6.5 | I14977: =IF(G14977="Male",VLOOKUP(H14977,'Shoe size conversion table'!$B$6:$D$22,2),VLOOKUP(H14977,'Shoe size conversion table'!$J$6:$L$22,2)) -> 37 | J14977: =IF(G14977="Male",VLOOKUP(H14977,'Shoe size conversion table'!$B$6:$D$22,3),VLOOKUP(H14977,'Shoe size conversion table'!$J$6:$L$22,3)) -> 4.5 | K14977: 139 | L14977: 0.1 | M14977: =YEAR(C14977) -> 1900 | N14977: =MONTH(C14977:C29943) -> 1 | O14977: =K14977*(1-L14977) -> 125.1
D14978: Germany | E14978: 2156 | F14978: GER1 | G14978: Female | H14978: 6.5 | I14978: =IF(G14978="Male",VLOOKUP(H14978,'Shoe size conversion table'!$B$6:$D$22,2),VLOOKUP(H14978,'Shoe size conversion table'!$J$6:$L$22,2)) -> 37 | J14978: =IF(G14978="Male",VLOOKUP(H14978,'Shoe size conversion table'!$B$6:$D$22,3),VLOOKUP(H14978,'Shoe size conversion table'!$J$6:$L$22,3)) -> 4.5 | K14978: 139 | L14978: 0.1 | M14978: =YEAR(C14978) -> 1900 | N14978: =MONTH(C14978:C29944) -> 1 | O14978: =K14978*(1-L14978) -> 125.1
D14979: Germany | E14979: 2156 | F14979: GER1 | G14979: Female | H14979: 6.5 | I14979: =IF(G14979="Male",VLOOKUP(H14979,'Shoe size conversion table'!$B$6:$D$22,2),VLOOKUP(H14979,'Shoe size conversion table'!$J$6:$L$22,2)) -> 37 | J14979: =IF(G14979="Male",VLOOKUP(H14979,'Shoe size conversion table'!$B$6:$D$22,3),VLOOKUP(H14979,'Shoe size conversion table'!$J$6:$L$22,3)) -> 4.5 | K14979: 139 | L14979: 0.1 | M14979: =YEAR(C14979) -> 1900 | N14979: =MONTH(C14979:C29945) -> 1 | O14979: =K14979*(1-L14979) -> 125.1
D14980: Germany | E14980: 2156 | F14980: GER1 | G14980: Female | H14980: 6.5 | I14980: =IF(G14980="Male",VLOOKUP(H14980,'Shoe size conversion table'!$B$6:$D$22,2),VLOOKUP(H14980,'Shoe size conversion table'!$J$6:$L$22,2)) -> 37 | J14980: =IF(G14980="Male",VLOOKUP(H14980,'Shoe size conversion table'!$B$6:$D$22,3),VLOOKUP(H14980,'Shoe size conversion table'!$J$6:$L$22,3)) -> 4.5 | K14980: 139 | L14980: 0.1 | M14980: =YEAR(C14980) -> 1900 | N14980: =MONTH(C14980:C29946) -> 1 | O14980: =K14980*(1-L14980) -> 125.1
D14981: Germany | E14981: 2156 | F14981: GER1 | G14981: Female | H14981: 6.5 | I14981: =IF(G14981="Male",VLOOKUP(H14981,'Shoe size conversion table'!$B$6:$D$22,2),VLOOKUP(H14981,'Shoe size conversion table'!$J$6:$L$22,2)) -> 37 | J14981: =IF(G14981="Male",VLOOKUP(H14981,'Shoe size conversion table'!$B$6:$D$22,3),VLOOKUP(H14981,'Shoe size conversion table'!$J$6:$L$22,3)) -> 4.5 | K14981: 139 | L14981: 0.1 | M14981: =YEAR(C14981) -> 1900 | N14981: =MONTH(C14981:C29947) -> 1 | O14981: =K14981*(1-L14981) -> 125.1

Sheet Shoe size conversion table
B1: Shoe size conversion tables
B3: Men sizes | J3: Women sizes
B5: US | C5: Europe | D5: UK | E5: Inches | F5: Centimetres | J5: US | K5: Europe | L5: UK | M5: Inches | N5: Centimetres
B6: 6 | C6: 39 | D6: 5.5 | E6: 9.25 | F6: 23.5 | J6: 4 | K6: 35 | L6: 2 | M6: 8.1875 | N6: 20.8
B7: 6.5 | C7: 39 | D7: 6 | E7: 9.5 | F7: 24.1 | J7: 4.5 | K7: 35 | L7: 2.5 | M7: 8.375 | N7: 21.3
B8: 7 | C8: 40 | D8: 6.5 | E8: 9.625 | F8: 24.4 | J8: 5 | K8: 35-36 | L8: 3 | M8: 8.5 | N8: 21.6
B9: 7.5 | C9: 40-41 | D9: 7 | E9: 9.75 | F9: 24.8 | J9: 5.5 | K9: 36 | L9: 3.5 | M9: 8.75 | N9: 22.2
B10: 8 | C10: 41 | D10: 7.5 | E10: 9.9375 | F10: 25.4 | J10: 6 | K10: 36-37 | L10: 4 | M10: 8.875 | N10: 22.5
B11: 8.5 | C11: 41-42 | D11: 8 | E11: 10.125 | F11: 25.7 | J11: 6.5 | K11: 37 | L11: 4.5 | M11: 9.0625 | N11: 23
B12: 9 | C12: 42 | D12: 8.5 | E12: 10.25 | F12: 26 | J12: 7 | K12: 37-38 | L12: 5 | M12: 9.25 | N12: 23.5
B13: 9.5 | C13: 42-43 | D13: 9 | E13: 10.4375 | F13: 26.7 | J13: 7.5 | K13: 38 | L13: 5.5 | M13: 9.375 | N13: 23.8
B14: 10 | C14: 43 | D14: 9.5 | E14: 10.5625 | F14: 27 | J14: 8 | K14: 38-39 | L14: 6 | M14: 9.5 | N14: 24.1
B15: 10.5 | C15: 43-44 | D15: 10 | E15: 10.75 | F15: 27.3 | J15: 8.5 | K15: 39 | L15: 6.5 | M15: 9.6875 | N15: 24.6
B16: 11 | C16: 44 | D16: 10.5 | E16: 10.9375 | F16: 27.9 | J16: 9 | K16: 39-40 | L16: 7 | M16: 9.875 | N16: 25.1
B17: 11.5 | C17: 44-45 | D17: 11 | E17: 11.125 | F17: 28.3 | J17: 9.5 | K17: 40 | L17: 7.5 | M17: 10 | N17: 25.4
B18: 12 | C18: 45 | D18: 11.5 | E18: 11.25 | F18: 28.6 | J18: 10 | K18: 40-41 | L18: 8 | M18: 10.1875 | N18: 25.9
B19: 13 | C19: 46 | D19: 12.5 | E19: 11.5625 | F19: 29.4 | J19: 10.5 | K19: 41 | L19: 8.5 | M19: 10.3125 | N19: 26.2
B20: 14 | C20: 47 | D20: 13.5 | E20: 11.875 | F20: 30.2 | J20: 11 | K20: 41-42 | L20: 9 | M20: 10.5 | N20: 26.7
B21: 15 | C21: 48 | D21: 14.5 | E21: 12.1875 | F21: 31 | J21: 11.5 | K21: 42 | L21: 9.5 | M21: 10.6875 | N21: 27.1
B22: 16 | C22: 49 | D22: 15.5 | E22: 12.5 | F22: 31.8 | J22: 12 | K22: 42-43 | L22: 10 | M22: 10.875 | N22: 27.6

Sheet Tasks 1,2
B1: Frequency distribution tables
B2: By size and month
B4: Task 1: Calculate the confidence intervals for men shoes sales in the USA, this time based on a bigger sample - 2015-2016.
B5: Task 2: Compare the results with the confidence intervals when the sample was based just on 2016.
B7: Solution: | AI7: Task 1 | AP7: Task 2
C9: United States, 2015 | P9: United States, 2016 | AC9: Mean | AE9: Standard error | AG9: Margin of error | AI9: 95% CI | AL9: Number of pairs, math round | AN9: Number of pairs, round up | AP9: Number of pairs (lesson) | AR9: Difference
B10: US | C10: 1 | D10: 2 | E10: 3 | F10: 4 | G10: 5 | H10: 6 | I10: 7 | J10: 8 | K10: 9 | L10: 10 | M10: 11 | N10: 12 | P10: 1 | Q10: 2 | R10: 3 | S10: 4 | T10: 5 | U10: 6 | V10: 7 | W10: 8 | X10: 9 | Y10: 10 | Z10: 11 | AA10: 12 | AC10: 15-'16 | AE10: 15-'16 | AG10: 15-'16 | AI10: 15-'16 | AR10: Lesson - Exercise
B11: 6 | C11: =COUNTIFS('Al Bundy'!$G$5:$G$14971,"Male",'Al Bundy'!$H$5:$H$14971,'Tasks 1,2'!$B11,'Al Bundy'!$M$5:$M$14971,"2015",'Al Bundy'!$N$5:$N$14971,'Tasks 1,2'!C$10,'Al Bundy'!$D$5:$D$14971,"United States") -> 0 | D11: =COUNTIFS('Al Bundy'!$G$5:$G$14971,"Male",'Al Bundy'!$H$5:$H$14971,'Tasks 1,2'!$B11,'Al Bundy'!$M$5:$M$14971,"2015",'Al Bundy'!$N$5:$N$14971,'Tasks 1,2'!D$10,'Al Bundy'!$D$5:$D$14971,"United States") -> 0 | E11: =COUNTIFS('Al Bundy'!$G$5:$G$14971,"Male",'Al Bundy'!$H$5:$H$14971,'Tasks 1,2'!$B11,'Al Bundy'!$M$5:$M$14971,"2015",'Al Bundy'!$N$5:$N$14971,'Tasks 1,2'!E$10,'Al Bundy'!$D$5:$D$14971,"United States") -> 0 | F11: =COUNTIFS('Al Bundy'!$G$5:$G$14971,"Male",'Al Bundy'!$H$5:$H$14971,'Tasks 1,2'!$B11,'Al Bundy'!$M$5:$M$14971,"2015",'Al Bundy'!$N$5:$N$14971,'Tasks 1,2'!F$10,'Al Bundy'!$D$5:$D$14971,"United States") -> 0 | G11: =COUNTIFS('Al Bundy'!$G$5:$G$14971,"Male",'Al Bundy'!$H$5:$H$14971,'Tasks 1,2'!$B11,'Al Bundy'!$M$5:$M$14971,"2015",'Al Bundy'!$N$5:$N$14971,'Tasks 1,2'!G$10,'Al Bundy'!$D$5:$D$14971,"United States") -> 3 | H11: =COUNTIFS('Al Bundy'!$G$5:$G$14971,"Male",'Al Bundy'!$H$5:$H$14971,'Tasks 1,2'!$B11,'Al Bundy'!$M$5:$M$14971,"2015",'Al Bundy'!$N$5:$N$14971,'Tasks 1,2'!H$10,'Al Bundy'!$D$5:$D$14971,"United States") -> 1 | I11: =COUNTIFS('Al Bundy'!$G$5:$G$14971,"Male",'Al Bundy'!$H$5:$H$14971,'Tasks 1,2'!$B11,'Al Bundy'!$M$5:$M$14971,"2015",'Al Bundy'!$N$5:$N$14971,'Tasks 1,2'!I$10,'Al Bundy'!$D$5:$D$14971,"United States") -> 1 | J11: =COUNTIFS('Al Bundy'!$G$5:$G$14971,"Male",'Al Bundy'!$H$5:$H$14971,'Tasks 1,2'!$B11,'Al Bundy'!$M$5:$M$14971,"2015",'Al Bundy'!$N$5:$N$14971,'Tasks 1,2'!J$10,'Al Bundy'!$D$5:$D$14971,"United States") -> 3 | ... N11: =COUNTIFS('Al Bundy'!$G$5:$G$14971,"Male",'Al Bundy'!$H$5:$H$14971,'Tasks 1,2'!$B11,'Al Bundy'!$M$5:$M$14971,"2015",'Al Bundy'!$N$5:$N$14971,'Tasks 1,2'!N$10,'Al Bundy'!$D$5:$D$14971,"United States") -> 0 | P11: =COUNTIFS('Al Bundy'!$G$5:$G$14971,"Male",'Al Bundy'!$H$5:$H$14971,'Tasks 1,2'!$B11,'Al Bundy'!$M$5:$M$14971,"2016",'Al Bundy'!$N$5:$N$14971,'Tasks 1,2'!P$10,'Al Bundy'!$D$5:$D$14971,"United States") -> 4 | Q11: =COUNTIFS('Al Bundy'!$G$5:$G$14971,"Male",'Al Bundy'!$H$5:$H$14971,'Tasks 1,2'!$B11,'Al Bundy'!$M$5:$M$14971,"2016",'Al Bundy'!$N$5:$N$14971,'Tasks 1,2'!Q$10,'Al Bundy'!$D$5:$D$14971,"United States") -> 1 | R11: =COUNTIFS('Al Bundy'!$G$5:$G$14971,"Male",'Al Bundy'!$H$5:$H$14971,'Tasks 1,2'!$B11,'Al Bundy'!$M$5:$M$14971,"2016",'Al Bundy'!$N$5:$N$14971,'Tasks 1,2'!R$10,'Al Bundy'!$D$5:$D$14971,"United States") -> 3 | S11: =COUNTIFS('Al Bundy'!$G$5:$G$14971,"Male",'Al Bundy'!$H$5:$H$14971,'Tasks 1,2'!$B11,'Al Bundy'!$M$5:$M$14971,"2016",'Al Bundy'!$N$5:$N$14971,'Tasks 1,2'!S$10,'Al Bundy'!$D$5:$D$14971,"United States") -> 1 | T11: =COUNTIFS('Al Bundy'!$G$5:$G$14971,"Male",'Al Bundy'!$H$5:$H$14971,'Tasks 1,2'!$B11,'Al Bundy'!$M$5:$M$14971,"2016",'Al Bundy'!$N$5:$N$14971,'Tasks 1,2'!T$10,'Al Bundy'!$D$5:$D$14971,"United States") -> 3 | U11: =COUNTIFS('Al Bundy'!$G$5:$G$14971,"Male",'Al Bundy'!$H$5:$H$14971,'Tasks 1,2'!$B11,'Al Bundy'!$M$5:$M$14971,"2016",'Al Bundy'!$N$5:$N$14971,'Tasks 1,2'!U$10,'Al Bundy'!$D$5:$D$14971,"United States") -> 3 | V11: =COUNTIFS('Al Bundy'!$G$5:$G$14971,"Male",'Al Bundy'!$H$5:$H$14971,'Tasks 1,2'!$B11,'Al Bundy'!$M$5:$M$14971,"2016",'Al Bundy'!$N$5:$N$14971,'Tasks 1,2'!V$10,'Al Bundy'!$D$5:$D$14971,"United States") -> 3 | W11: =COUNTIFS('Al Bundy'!$G$5:$G$14971,"Male",'Al Bundy'!$H$5:$H$14971,'Tasks 1,2'!$B11,'Al Bundy'!$M$5:$M$14971,"2016",'Al Bundy'!$N$5:$N$14971,'Tasks 1,2'!W$10,'Al Bundy'!$D$5:$D$14971,"United States") -> 4 | ... AA11: =COUNTIFS('Al Bundy'!$G$5:$G$14971,"Male",'Al Bundy'!$H$5:$H$14971,'Tasks 1,2'!$B11,'Al Bundy'!$M$5:$M$14971,"2016",'Al Bundy'!$N$5:$N$14971,'Tasks 1,2'!AA$10,'Al Bundy'!$D$5:$D$14971,"United States") -> 0 | AC11: =AVERAGE(C11:AA11) -> 2.1666667 | AE11: =_xlfn.STDEV.S(C11:AA11)/SQRT($AJ$31) -> 0.39317855 | AG11: =AE11*$AJ$32 -> 0.81348642 | AI11: =AC11-AG11 -> 1.3531802 | AJ11: =AC11+AG11 -> 2.9801531 | AL11: =ROUND(AJ11,0) -> 3 | AN11: =ROUNDUP(AJ11,0) -> 3 | AP11: 4.0373597 | AR11: =AP11-AL11 -> 1.0373597
B12: 6.5 | C12: =COUNTIFS('Al Bundy'!$G$5:$G$14971,"Male",'Al Bundy'!$H$5:$H$14971,'Tasks 1,2'!$B12,'Al Bundy'!$M$5:$M$14971,"2015",'Al Bundy'!$N$5:$N$14971,'Tasks 1,2'!C$10,'Al Bundy'!$D$5:$D$14971,"United States") -> 4 | D12: =COUNTIFS('Al Bundy'!$G$5:$G$14971,"Male",'Al Bundy'!$H$5:$H$14971,'Tasks 1,2'!$B12,'Al Bundy'!$M$5:$M$14971,"2015",'Al Bundy'!$N$5:$N$14971,'Tasks 1,2'!D$10,'Al Bundy'!$D$5:$D$14971,"United States") -> 1 | E12: =COUNTIFS('Al Bundy'!$G$5:$G$14971,"Male",'Al Bundy'!$H$5:$H$14971,'Tasks 1,2'!$B12,'Al Bundy'!$M$5:$M$14971,"2015",'Al Bundy'!$N$5:$N$14971,'Tasks 1,2'!E$10,'Al Bundy'!$D$5:$D$14971,"United States") -> 0 | F12: =COUNTIFS('Al Bundy'!$G$5:$G$14971,"Male",'Al Bundy'!$H$5:$H$14971,'Tasks 1,2'!$B12,'Al Bundy'!$M$5:$M$14971,"2015",'Al Bundy'!$N$5:$N$14971,'Tasks 1,2'!F$10,'Al Bundy'!$D$5:$D$14971,"United States") -> 1 | G12: =COUNTIFS('Al Bundy'!$G$5:$G$14971,"Male",'Al Bundy'!$H$5:$H$14971,'Tasks 1,2'!$B12,'Al Bundy'!$M$5:$M$14971,"2015",'Al Bundy'!$N$5:$N$14971,'Tasks 1,2'!G$10,'Al Bundy'!$D$5:$D$14971,"United States") -> 0 | H12: =COUNTIFS('Al Bundy'!$G$5:$G$14971,"Male",'Al Bundy'!$H$5:$H$14971,'Tasks 1,2'!$B12,'Al Bundy'!$M$5:$M$14971,"2015",'Al Bundy'!$N$5:$N$14971,'Tasks 1,2'!H$10,'Al Bundy'!$D$5:$D$14971,"United States") -> 0 | I12: =COUNTIFS('Al Bundy'!$G$5:$G$14971,"Male",'Al Bundy'!$H$5:$H$14971,'Tasks 1,2'!$B12,'Al Bundy'!$M$5:$M$14971,"2015",'Al Bundy'!$N$5:$N$14971,'Tasks 1,2'!I$10,'Al Bundy'!$D$5:$D$14971,"United States") -> 2 | J12: =COUNTIFS('Al Bundy'!$G$5:$G$14971,"Male",'Al Bundy'!$H$5:$H$14971,'Tasks 1,2'!$B12,'Al Bundy'!$M$5:$M$14971,"2015",'Al Bundy'!$N$5:$N$14971,'Tasks 1,2'!J$10,'Al Bundy'!$D$5:$D$14971,"United States") -> 3 | ... N12: =COUNTIFS('Al Bundy'!$G$5:$G$14971,"Male",'Al Bundy'!$H$5:$H$14971,'Tasks 1,2'!$B12,'Al Bundy'!$M$5:$M$14971,"2015",'Al Bundy'!$N$5:$N$14971,'Tasks 1,2'!N$10,'Al Bundy'!$D$5:$D$14971,"United States") -> 3 | P12: =COUNTIFS('Al Bundy'!$G$5:$G$14971,"Male",'Al Bundy'!$H$5:$H$14971,'Tasks 1,2'!$B12,'Al Bundy'!$M$5:$M$14971,"2016",'Al Bundy'!$N$5:$N$14971,'Tasks 1,2'!P$10,'Al Bundy'!$D$5:$D$14971,"United States") -> 3 | Q12: =COUNTIFS('Al Bundy'!$G$5:$G$14971,"Male",'Al Bundy'!$H$5:$H$14971,'Tasks 1,2'!$B12,'Al Bundy'!$M$5:$M$14971,"2016",'Al Bundy'!$N$5:$N$14971,'Tasks 1,2'!Q$10,'Al Bundy'!$D$5:$D$14971,"United States") -> 2 | R12: =COUNTIFS('Al Bundy'!$G$5:$G$14971,"Male",'Al Bundy'!$H$5:$H$14971,'Tasks 1,2'!$B12,'Al Bundy'!$M$5:$M$14971,"2016",'Al Bundy'!$N$5:$N$14971,'Tasks 1,2'!R$10,'Al Bundy'!$D$5:$D$14971,"United States") -> 0 | S12: =COUNTIFS('Al Bundy'!$G$5:$G$14971,"Male",'Al Bundy'!$H$5:$H$14971,'Tasks 1,2'!$B12,'Al Bundy'!$M$5:$M$14971,"2016",'Al Bundy'!$N$5:$N$14971,'Tasks 1,2'!S$10,'Al Bundy'!$D$5:$D$14971,"United States") -> 1 | T12: =COUNTIFS('Al Bundy'!$G$5:$G$14971,"Male",'Al Bundy'!$H$5:$H$14971,'Tasks 1,2'!$B12,'Al Bundy'!$M$5:$M$14971,"2016",'Al Bundy'!$N$5:$N$14971,'Tasks 1,2'!T$10,'Al Bundy'!$D$5:$D$14971,"United States") -> 0 | U12: =COUNTIFS('Al Bundy'!$G$5:$G$14971,"Male",'Al Bundy'!$H$5:$H$14971,'Tasks 1,2'!$B12,'Al Bundy'!$M$5:$M$14971,"2016",'Al Bundy'!$N$5:$N$14971,'Tasks 1,2'!U$10,'Al Bundy'!$D$5:$D$14971,"United States") -> 0 | V12: =COUNTIFS('Al Bundy'!$G$5:$G$14971,"Male",'Al Bundy'!$H$5:$H$14971,'Tasks 1,2'!$B12,'Al Bundy'!$M$5:$M$14971,"2016",'Al Bundy'!$N$5:$N$14971,'Tasks 1,2'!V$10,'Al Bundy'!$D$5:$D$14971,"United States") -> 1 | W12: =COUNTIFS('Al Bundy'!$G$5:$G$14971,"Male",'Al Bundy'!$H$5:$H$14971,'Tasks 1,2'!$B12,'Al Bundy'!$M$5:$M$14971,"2016",'Al Bundy'!$N$5:$N$14971,'Tasks 1,2'!W$10,'Al Bundy'!$D$5:$D$14971,"United States") -> 7 | ... AA12: =COUNTIFS('Al Bundy'!$G$5:$G$14971,"Male",'Al Bundy'!$H$5:$H$14971,'Tasks 1,2'!$B12,'Al Bundy'!$M$5:$M$14971,"2016",'Al Bundy'!$N$5:$N$14971,'Tasks 1,2'!AA$10,'Al Bundy'!$D$5:$D$14971,"United States") -> 1 | AC12: =AVERAGE(C12:AA12) -> 1.5833333 | AE12: =_xlfn.STDEV.S(C12:AA12)/SQRT($AJ$31) -> 0.34005896 | AG12: =AE12*$AJ$32 -> 0.70358199 | AI12: =AC12-AG12 -> 0.87975134 | AJ12: =AC12+AG12 -> 2.2869153 | AL12: =ROUND(AJ12,0) -> 2 | AN12: =ROUNDUP(AJ12,0) -> 3 | AP12: 2.8761212 | AR12: =AP12-AL12 -> 0.87612122
B13: 7 | C13: =COUNTIFS('Al Bundy'!$G$5:$G$14971,"Male",'Al Bundy'!$H$5:$H$14971,'Tasks 1,2'!$B13,'Al Bundy'!$M$5:$M$14971,"2015",'Al Bundy'!$N$5:$N$14971,'Tasks 1,2'!C$10,'Al Bundy'!$D$5:$D$14971,"United States") -> 0 | D13: =COUNTIFS('Al Bundy'!$G$5:$G$14971,"Male",'Al Bundy'!$H$5:$H$14971,'Tasks 1,2'!$B13,'Al Bundy'!$M$5:$M$14971,"2015",'Al Bundy'!$N$5:$N$14971,'Tasks 1,2'!D$10,'Al Bundy'!$D$5:$D$14971,"United States") -> 0 | E13: =COUNTIFS('Al Bundy'!$G$5:$G$14971,"Male",'Al Bundy'!$H$5:$H$14971,'Tasks 1,2'!$B13,'Al Bundy'!$M$5:$M$14971,"2015",'Al Bundy'!$N$5:$N$14971,'Tasks 1,2'!E$10,'Al Bundy'!$D$5:$D$14971,"United States") -> 0 | F13: =COUNTIFS('Al Bundy'!$G$5:$G$14971,"Male",'Al Bundy'!$H$5:$H$14971,'Tasks 1,2'!$B13,'Al Bundy'!$M$5:$M$14971,"2015",'Al Bundy'!$N$5:$N$14971,'Tasks 1,2'!F$10,'Al Bundy'!$D$5:$D$14971,"United States") -> 0 | G13: =COUNTIFS('Al Bundy'!$G$5:$G$14971,"Male",'Al Bundy'!$H$5:$H$14971,'Tasks 1,2'!$B13,'Al Bundy'!$M$5:$M$14971,"2015",'Al Bundy'!$N$5:$N$14971,'Tasks 1,2'!G$10,'Al Bundy'!$D$5:$D$14971,"United States") -> 1 | H13: =COUNTIFS('Al Bundy'!$G$5:$G$14971,"Male",'Al Bundy'!$H$5:$H$14971,'Tasks 1,2'!$B13,'Al Bundy'!$M$5:$M$14971,"2015",'Al Bundy'!$N$5:$N$14971,'Tasks 1,2'!H$10,'Al Bundy'!$D$5:$D$14971,"United States") -> 2 | I13: =COUNTIFS('Al Bundy'!$G$5:$G$14971,"Male",'Al Bundy'!$H$5:$H$14971,'Tasks 1,2'!$B13,'Al Bundy'!$M$5:$M$14971,"2015",'Al Bundy'!$N$5:$N$14971,'Tasks 1,2'!I$10,'Al Bundy'!$D$5:$D$14971,"United States") -> 1 | J13: =COUNTIFS('Al Bundy'!$G$5:$G$14971,"Male",'Al Bundy'!$H$5:$H$14971,'Tasks 1,2'!$B13,'Al Bundy'!$M$5:$M$14971,"2015",'Al Bundy'!$N$5:$N$14971,'Tasks 1,2'!J$10,'Al Bundy'!$D$5:$D$14971,"United States") -> 0 | ... N13: =COUNTIFS('Al Bundy'!$G$5:$G$14971,"Male",'Al Bundy'!$H$5:$H$14971,'Tasks 1,2'!$B13,'Al Bundy'!$M$5:$M$14971,"2015",'Al Bundy'!$N$5:$N$14971,'Tasks 1,2'!N$10,'Al Bundy'!$D$5:$D$14971,"United States") -> 3 | P13: =COUNTIFS('Al Bundy'!$G$5:$G$14971,"Male",'Al Bundy'!$H$5:$H$14971,'Tasks 1,2'!$B13,'Al Bundy'!$M$5:$M$14971,"2016",'Al Bundy'!$N$5:$N$14971,'Tasks 1,2'!P$10,'Al Bundy'!$D$5:$D$14971,"United States") -> 0 | Q13: =COUNTIFS('Al Bundy'!$G$5:$G$14971,"Male",'Al Bundy'!$H$5:$H$14971,'Tasks 1,2'!$B13,'Al Bundy'!$M$5:$M$14971,"2016",'Al Bundy'!$N$5:$N$14971,'Tasks 1,2'!Q$10,'Al Bundy'!$D$5:$D$14971,"United States") -> 0 | R13: =COUNTIFS('Al Bundy'!$G$5:$G$14971,"Male",'Al Bundy'!$H$5:$H$14971,'Tasks 1,2'!$B13,'Al Bundy'!$M$5:$M$14971,"2016",'Al Bundy'!$N$5:$N$14971,'Tasks 1,2'!R$10,'Al Bundy'!$D$5:$D$14971,"United States") -> 1 | S13: =COUNTIFS('Al Bundy'!$G$5:$G$14971,"Male",'Al Bundy'!$H$5:$H$14971,'Tasks 1,2'!$B13,'Al Bundy'!$M$5:$M$14971,"2016",'Al Bundy'!$N$5:$N$14971,'Tasks 1,2'!S$10,'Al Bundy'!$D$5:$D$14971,"United States") -> 0 | T13: =COUNTIFS('Al Bundy'!$G$5:$G$14971,"Male",'Al Bundy'!$H$5:$H$14971,'Tasks 1,2'!$B13,'Al Bundy'!$M$5:$M$14971,"2016",'Al Bundy'!$N$5:$N$14971,'Tasks 1,2'!T$10,'Al Bundy'!$D$5:$D$14971,"United States") -> 6 | U13: =COUNTIFS('Al Bundy'!$G$5:$G$14971,"Male",'Al Bundy'!$H$5:$H$14971,'Tasks 1,2'!$B13,'Al Bundy'!$M$5:$M$14971,"2016",'Al Bundy'!$N$5:$N$14971,'Tasks 1,2'!U$10,'Al Bundy'!$D$5:$D$14971,"United States") -> 4 | V13: =COUNTIFS('Al Bundy'!$G$5:$G$14971,"Male",'Al Bundy'!$H$5:$H$14971,'Tasks 1,2'!$B13,'Al Bundy'!$M$5:$M$14971,"2016",'Al Bundy'!$N$5:$N$14971,'Tasks 1,2'!V$10,'Al Bundy'!$D$5:$D$14971,"United States") -> 4 | W13: =COUNTIFS('Al Bundy'!$G$5:$G$14971,"Male",'Al Bundy'!$H$5:$H$14971,'Tasks 1,2'!$B13,'Al Bundy'!$M$5:$M$14971,"2016",'Al Bundy'!$N$5:$N$14971,'Tasks 1,2'!W$10,'Al Bundy'!$D$5:$D$14971,"United States") -> 2 | ... AA13: =COUNTIFS('Al Bundy'!$G$5:$G$14971,"Male",'Al Bundy'!$H$5:$H$14971,'Tasks 1,2'!$B13,'Al Bundy'!$M$5:$M$14971,"2016",'Al Bundy'!$N$5:$N$14971,'Tasks 1,2'!AA$10,'Al Bundy'!$D$5:$D$14971,"United States") -> 0 | AC13: =AVERAGE(C13:AA13) -> 1.3333333 | AE13: =_xlfn.STDEV.S(C13:AA13)/SQRT($AJ$31) -> 0.33872452 | AG13: =AE13*$AJ$32 -> 0.70082103 | AI13: =AC13-AG13 -> 0.6325123 | AJ13: =AC13+AG13 -> 2.0341544 | AL13: =ROUND(AJ13,0) -> 2 | AN13: =ROUNDUP(AJ13,0) -> 3 | AP13: 2.9897465 | AR13: =AP13-AL13 -> 0.98974655
B14: 7.5 | C14: =COUNTIFS('Al Bundy'!$G$5:$G$14971,"Male",'Al Bundy'!$H$5:$H$14971,'Tasks 1,2'!$B14,'Al Bundy'!$M$5:$M$14971,"2015",'Al Bundy'!$N$5:$N$14971,'Tasks 1,2'!C$10,'Al Bundy'!$D$5:$D$14971,"United States") -> 0 | D14: =COUNTIFS('Al Bundy'!$G$5:$G$14971,"Male",'Al Bundy'!$H$5:$H$14971,'Tasks 1,2'!$B14,'Al Bundy'!$M$5:$M$14971,"2015",'Al Bundy'!$N$5:$N$14971,'Tasks 1,2'!D$10,'Al Bundy'!$D$5:$D$14971,"United States") -> 1 | E14: =COUNTIFS('Al Bundy'!$G$5:$G$14971,"Male",'Al Bundy'!$H$5:$H$14971,'Tasks 1,2'!$B14,'Al Bundy'!$M$5:$M$14971,"2015",'Al Bundy'!$N$5:$N$14971,'Tasks 1,2'!E$10,'Al Bundy'!$D$5:$D$14971,"United States") -> 2 | F14: =COUNTIFS('Al Bundy'!$G$5:$G$14971,"Male",'Al Bundy'!$H$5:$H$14971,'Tasks 1,2'!$B14,'Al Bundy'!$M$5:$M$14971,"2015",'Al Bundy'!$N$5:$N$14971,'Tasks 1,2'!F$10,'Al Bundy'!$D$5:$D$14971,"United States") -> 1 | G14: =COUNTIFS('Al Bundy'!$G$5:$G$14971,"Male",'Al Bundy'!$H$5:$H$14971,'Tasks 1,2'!$B14,'Al Bundy'!$M$5:$M$14971,"2015",'Al Bundy'!$N$5:$N$14971,'Tasks 1,2'!G$10,'Al Bundy'!$D$5:$D$14971,"United States") -> 0 | H14: =COUNTIFS('Al Bundy'!$G$5:$G$14971,"Male",'Al Bundy'!$H$5:$H$14971,'Tasks 1,2'!$B14,'Al Bundy'!$M$5:$M$14971,"2015",'Al Bundy'!$N$5:$N$14971,'Tasks 1,2'!H$10,'Al Bundy'!$D$5:$D$14971,"United States") -> 0 | I14: =COUNTIFS('Al Bundy'!$G$5:$G$14971,"Male",'Al Bundy'!$H$5:$H$14971,'Tasks 1,2'!$B14,'Al Bundy'!$M$5:$M$14971,"2015",'Al Bundy'!$N$5:$N$14971,'Tasks 1,2'!I$10,'Al Bundy'!$D$5:$D$14971,"United States") -> 3 | J14: =COUNTIFS('Al Bundy'!$G$5:$G$14971,"Male",'Al Bundy'!$H$5:$H$14971,'Tasks 1,2'!$B14,'Al Bundy'!$M$5:$M$14971,"2015",'Al Bundy'!$N$5:$N$14971,'Tasks 1,2'!J$10,'Al Bundy'!$D$5:$D$14971,"United States") -> 2 | ... N14: =COUNTIFS('Al Bundy'!$G$5:$G$14971,"Male",'Al Bundy'!$H$5:$H$14971,'Tasks 1,2'!$B14,'Al Bundy'!$M$5:$M$14971,"2015",'Al Bundy'!$N$5:$N$14971,'Tasks 1,2'!N$10,'Al Bundy'!$D$5:$D$14971,"United States") -> 2 | P14: =COUNTIFS('Al Bundy'!$G$5:$G$14971,"Male",'Al Bundy'!$H$5:$H$14971,'Tasks 1,2'!$B14,'Al Bundy'!$M$5:$M$14971,"2016",'Al Bundy'!$N$5:$N$14971,'Tasks 1,2'!P$10,'Al Bundy'!$D$5:$D$14971,"United States") -> 3 | Q14: =COUNTIFS('Al Bundy'!$G$5:$G$14971,"Male",'Al Bundy'!$H$5:$H$14971,'Tasks 1,2'!$B14,'Al Bundy'!$M$5:$M$14971,"2016",'Al Bundy'!$N$5:$N$14971,'Tasks 1,2'!Q$10,'Al Bundy'!$D$5:$D$14971,"United States") -> 2 | R14: =COUNTIFS('Al Bundy'!$G$5:$G$14971,"Male",'Al Bundy'!$H$5:$H$14971,'Tasks 1,2'!$B14,'Al Bundy'!$M$5:$M$14971,"2016",'Al Bundy'!$N$5:$N$14971,'Tasks 1,2'!R$10,'Al Bundy'!$D$5:$D$14971,"United States") -> 3 | S14: =COUNTIFS('Al Bundy'!$G$5:$G$14971,"Male",'Al Bundy'!$H$5:$H$14971,'Tasks 1,2'!$B14,'Al Bundy'!$M$5:$M$14971,"2016",'Al Bundy'!$N$5:$N$14971,'Tasks 1,2'!S$10,'Al Bundy'!$D$5:$D$14971,"United States") -> 1 | T14: =COUNTIFS('Al Bundy'!$G$5:$G$14971,"Male",'Al Bundy'!$H$5:$H$14971,'Tasks 1,2'!$B14,'Al Bundy'!$M$5:$M$14971,"2016",'Al Bundy'!$N$5:$N$14971,'Tasks 1,2'!T$10,'Al Bundy'!$D$5:$D$14971,"United States") -> 7 | U14: =COUNTIFS('Al Bundy'!$G$5:$G$14971,"Male",'Al Bundy'!$H$5:$H$14971,'Tasks 1,2'!$B14,'Al Bundy'!$M$5:$M$14971,"2016",'Al Bundy'!$N$5:$N$14971,'Tasks 1,2'!U$10,'Al Bundy'!$D$5:$D$14971,"United States") -> 0 | V14: =COUNTIFS('Al Bundy'!$G$5:$G$14971,"Male",'Al Bundy'!$H$5:$H$14971,'Tasks 1,2'!$B14,'Al Bundy'!$M$5:$M$14971,"2016",'Al Bundy'!$N$5:$N$14971,'Tasks 1,2'!V$10,'Al Bundy'!$D$5:$D$14971,"United States") -> 7 | W14: =COUNTIFS('Al Bundy'!$G$5:$G$14971,"Male",'Al Bundy'!$H$5:$H$14971,'Tasks 1,2'!$B14,'Al Bundy'!$M$5:$M$14971,"2016",'Al Bundy'!$N$5:$N$14971,'Tasks 1,2'!W$10,'Al Bundy'!$D$5:$D$14971,"United States") -> 3 | ... AA14: =COUNTIFS('Al Bundy'!$G$5:$G$14971,"Male",'Al Bundy'!$H$5:$H$14971,'Tasks 1,2'!$B14,'Al Bundy'!$M$5:$M$14971,"2016",'Al Bundy'!$N$5:$N$14971,'Tasks 1,2'!AA$10,'Al Bundy'!$D$5:$D$14971,"United States") -> 1 | AC14: =AVERAGE(C14:AA14) -> 2.3333333 | AE14: =_xlfn.STDEV.S(C14:AA14)/SQRT($AJ$31) -> 0.41119597 | AG14: =AE14*$AJ$32 -> 0.85076446 | AI14: =AC14-AG14 -> 1.4825689 | AJ14: =AC14+AG14 -> 3.1840978 | AL14: =ROUND(AJ14,0) -> 3 | AN14: =ROUNDUP(AJ14,0) -> 4 | AP14: 4.6799712 | AR14: =AP14-AL14 -> 1.6799712
B15: 8 | C15: =COUNTIFS('Al Bundy'!$G$5:$G$14971,"Male",'Al Bundy'!$H$5:$H$14971,'Tasks 1,2'!$B15,'Al Bundy'!$M$5:$M$14971,"2015",'Al Bundy'!$N$5:$N$14971,'Tasks 1,2'!C$10,'Al Bundy'!$D$5:$D$14971,"United States") -> 5 | D15: =COUNTIFS('Al Bundy'!$G$5:$G$14971,"Male",'Al Bundy'!$H$5:$H$14971,'Tasks 1,2'!$B15,'Al Bundy'!$M$5:$M$14971,"2015",'Al Bundy'!$N$5:$N$14971,'Tasks 1,2'!D$10,'Al Bundy'!$D$5:$D$14971,"United States") -> 3 | E15: =COUNTIFS('Al Bundy'!$G$5:$G$14971,"Male",'Al Bundy'!$H$5:$H$14971,'Tasks 1,2'!$B15,'Al Bundy'!$M$5:$M$14971,"2015",'Al Bundy'!$N$5:$N$14971,'Tasks 1,2'!E$10,'Al Bundy'!$D$5:$D$14971,"United States") -> 1 | F15: =COUNTIFS('Al Bundy'!$G$5:$G$14971,"Male",'Al Bundy'!$H$5:$H$14971,'Tasks 1,2'!$B15,'Al Bundy'!$M$5:$M$14971,"2015",'Al Bundy'!$N$5:$N$14971,'Tasks 1,2'!F$10,'Al Bundy'!$D$5:$D$14971,"United States") -> 0 | G15: =COUNTIFS('Al Bundy'!$G$5:$G$14971,"Male",'Al Bundy'!$H$5:$H$14971,'Tasks 1,2'!$B15,'Al Bundy'!$M$5:$M$14971,"2015",'Al Bundy'!$N$5:$N$14971,'Tasks 1,2'!G$10,'Al Bundy'!$D$5:$D$14971,"United States") -> 6 | H15: =COUNTIFS('Al Bundy'!$G$5:$G$14971,"Male",'Al Bundy'!$H$5:$H$14971,'Tasks 1,2'!$B15,'Al Bundy'!$M$5:$M$14971,"2015",'Al Bundy'!$N$5:$N$14971,'Tasks 1,2'!H$10,'Al Bundy'!$D$5:$D$14971,"United States") -> 6 | I15: =COUNTIFS('Al Bundy'!$G$5:$G$14971,"Male",'Al Bundy'!$H$5:$H$14971,'Tasks 1,2'!$B15,'Al Bundy'!$M$5:$M$14971,"2015",'Al Bundy'!$N$5:$N$14971,'Tasks 1,2'!I$10,'Al Bundy'!$D$5:$D$14971,"United States") -> 4 | J15: =COUNTIFS('Al Bundy'!$G$5:$G$14971,"Male",'Al Bundy'!$H$5:$H$14971,'Tasks 1,2'!$B15,'Al Bundy'!$M$5:$M$14971,"2015",'Al Bundy'!$N$5:$N$14971,'Tasks 1,2'!J$10,'Al Bundy'!$D$5:$D$14971,"United States") -> 0 | ... N15: =COUNTIFS('Al Bundy'!$G$5:$G$14971,"Male",'Al Bundy'!$H$5:$H$14971,'Tasks 1,2'!$B15,'Al Bundy'!$M$5:$M$14971,"2015",'Al Bundy'!$N$5:$N$14971,'Tasks 1,2'!N$10,'Al Bundy'!$D$5:$D$14971,"United States") -> 3 | P15: =COUNTIFS('Al Bundy'!$G$5:$G$14971,"Male",'Al Bundy'!$H$5:$H$14971,'Tasks 1,2'!$B15,'Al Bundy'!$M$5:$M$14971,"2016",'Al Bundy'!$N$5:$N$14971,'Tasks 1,2'!P$10,'Al Bundy'!$D$5:$D$14971,"United States") -> 7 | Q15: =COUNTIFS('Al Bundy'!$G$5:$G$14971,"Male",'Al Bundy'!$H$5:$H$14971,'Tasks 1,2'!$B15,'Al Bundy'!$M$5:$M$14971,"2016",'Al Bundy'!$N$5:$N$14971,'Tasks 1,2'!Q$10,'Al Bundy'!$D$5:$D$14971,"United States") -> 9 | R15: =COUNTIFS('Al Bundy'!$G$5:$G$14971,"Male",'Al Bundy'!$H$5:$H$14971,'Tasks 1,2'!$B15,'Al Bundy'!$M$5:$M$14971,"2016",'Al Bundy'!$N$5:$N$14971,'Tasks 1,2'!R$10,'Al Bundy'!$D$5:$D$14971,"United States") -> 7 | S15: =COUNTIFS('Al Bundy'!$G$5:$G$14971,"Male",'Al Bundy'!$H$5:$H$14971,'Tasks 1,2'!$B15,'Al Bundy'!$M$5:$M$14971,"2016",'Al Bundy'!$N$5:$N$14971,'Tasks 1,2'!S$10,'Al Bundy'!$D$5:$D$14971,"United States") -> 3 | T15: =COUNTIFS('Al Bundy'!$G$5:$G$14971,"Male",'Al Bundy'!$H$5:$H$14971,'Tasks 1,2'!$B15,'Al Bundy'!$M$5:$M$14971,"2016",'Al Bundy'!$N$5:$N$14971,'Tasks 1,2'!T$10,'Al Bundy'!$D$5:$D$14971,"United States") -> 12 | U15: =COUNTIFS('Al Bundy'!$G$5:$G$14971,"Male",'Al Bundy'!$H$5:$H$14971,'Tasks 1,2'!$B15,'Al Bundy'!$M$5:$M$14971,"2016",'Al Bundy'!$N$5:$N$14971,'Tasks 1,2'!U$10,'Al Bundy'!$D$5:$D$14971,"United States") -> 2 | V15: =COUNTIFS('Al Bundy'!$G$5:$G$14971,"Male",'Al Bundy'!$H$5:$H$14971,'Tasks 1,2'!$B15,'Al Bundy'!$M$5:$M$14971,"2016",'Al Bundy'!$N$5:$N$14971,'Tasks 1,2'!V$10,'Al Bundy'!$D$5:$D$14971,"United States") -> 9 | W15: =COUNTIFS('Al Bundy'!$G$5:$G$14971,"Male",'Al Bundy'!$H$5:$H$14971,'Tasks 1,2'!$B15,'Al Bundy'!$M$5:$M$14971,"2016",'Al Bundy'!$N$5:$N$14971,'Tasks 1,2'!W$10,'Al Bundy'!$D$5:$D$14971,"United States") -> 4 | ... AA15: =COUNTIFS('Al Bundy'!$G$5:$G$14971,"Male",'Al Bundy'!$H$5:$H$14971,'Tasks 1,2'!$B15,'Al Bundy'!$M$5:$M$14971,"2016",'Al Bundy'!$N$5:$N$14971,'Tasks 1,2'!AA$10,'Al Bundy'!$D$5:$D$14971,"United States") -> 6 | AC15: =AVERAGE(C15:AA15) -> 4.7916667 | AE15: =_xlfn.STDEV.S(C15:AA15)/SQRT($AJ$31) -> 0.59884904 | AG15: =AE15*$AJ$32 -> 1.2390187 | AI15: =AC15-AG15 -> 3.552648 | AJ15: =AC15+AG15 -> 6.0306853 | AL15: =ROUND(AJ15,0) -> 6 | AN15: =ROUNDUP(AJ15,0) -> 7 | AP15: 8.007369 | AR15: =AP15-AL15 -> 2.007369
B16: 8.5 | C16: =COUNTIFS('Al Bundy'!$G$5:$G$14971,"Male",'Al Bundy'!$H$5:$H$14971,'Tasks 1,2'!$B16,'Al Bundy'!$M$5:$M$14971,"2015",'Al Bundy'!$N$5:$N$14971,'Tasks 1,2'!C$10,'Al Bundy'!$D$5:$D$14971,"United States") -> 4 | D16: =COUNTIFS('Al Bundy'!$G$5:$G$14971,"Male",'Al Bundy'!$H$5:$H$14971,'Tasks 1,2'!$B16,'Al Bundy'!$M$5:$M$14971,"2015",'Al Bundy'!$N$5:$N$14971,'Tasks 1,2'!D$10,'Al Bundy'!$D$5:$D$14971,"United States") -> 5 | E16: =COUNTIFS('Al Bundy'!$G$5:$G$14971,"Male",'Al Bundy'!$H$5:$H$14971,'Tasks 1,2'!$B16,'Al Bundy'!$M$5:$M$14971,"2015",'Al Bundy'!$N$5:$N$14971,'Tasks 1,2'!E$10,'Al Bundy'!$D$5:$D$14971,"United States") -> 3 | F16: =COUNTIFS('Al Bundy'!$G$5:$G$14971,"Male",'Al Bundy'!$H$5:$H$14971,'Tasks 1,2'!$B16,'Al Bundy'!$M$5:$M$14971,"2015",'Al Bundy'!$N$5:$N$14971,'Tasks 1,2'!F$10,'Al Bundy'!$D$5:$D$14971,"United States") -> 1 | G16: =COUNTIFS('Al Bundy'!$G$5:$G$14971,"Male",'Al Bundy'!$H$5:$H$14971,'Tasks 1,2'!$B16,'Al Bundy'!$M$5:$M$14971,"2015",'Al Bundy'!$N$5:$N$14971,'Tasks 1,2'!G$10,'Al Bundy'!$D$5:$D$14971,"United States") -> 2 | H16: =COUNTIFS('Al Bundy'!$G$5:$G$14971,"Male",'Al Bundy'!$H$5:$H$14971,'Tasks 1,2'!$B16,'Al Bundy'!$M$5:$M$14971,"2015",'Al Bundy'!$N$5:$N$14971,'Tasks 1,2'!H$10,'Al Bundy'!$D$5:$D$14971,"United States") -> 11 | I16: =COUNTIFS('Al Bundy'!$G$5:$G$14971,"Male",'Al Bundy'!$H$5:$H$14971,'Tasks 1,2'!$B16,'Al Bundy'!$M$5:$M$14971,"2015",'Al Bundy'!$N$5:$N$14971,'Tasks 1,2'!I$10,'Al Bundy'!$D$5:$D$14971,"United States") -> 6 | J16: =COUNTIFS('Al Bundy'!$G$5:$G$14971,"Male",'Al Bundy'!$H$5:$H$14971,'Tasks 1,2'!$B16,'Al Bundy'!$M$5:$M$14971,"2015",'Al Bundy'!$N$5:$N$14971,'Tasks 1,2'!J$10,'Al Bundy'!$D$5:$D$14971,"United States") -> 6 | ... N16: =COUNTIFS('Al Bundy'!$G$5:$G$14971,"Male",'Al Bundy'!$H$5:$H$14971,'Tasks 1,2'!$B16,'Al Bundy'!$M$5:$M$14971,"2015",'Al Bundy'!$N$5:$N$14971,'Tasks 1,2'!N$10,'Al Bundy'!$D$5:$D$14971,"United States") -> 2 | P16: =COUNTIFS('Al Bundy'!$G$5:$G$14971,"Male",'Al Bundy'!$H$5:$H$14971,'Tasks 1,2'!$B16,'Al Bundy'!$M$5:$M$14971,"2016",'Al Bundy'!$N$5:$N$14971,'Tasks 1,2'!P$10,'Al Bundy'!$D$5:$D$14971,"United States") -> 12 | Q16: =COUNTIFS('Al Bundy'!$G$5:$G$14971,"Male",'Al Bundy'!$H$5:$H$14971,'Tasks 1,2'!$B16,'Al Bundy'!$M$5:$M$14971,"2016",'Al Bundy'!$N$5:$N$14971,'Tasks 1,2'!Q$10,'Al Bundy'!$D$5:$D$14971,"United States") -> 12 | R16: =COUNTIFS('Al Bundy'!$G$5:$G$14971,"Male",'Al Bundy'!$H$5:$H$14971,'Tasks 1,2'!$B16,'Al Bundy'!$M$5:$M$14971,"2016",'Al Bundy'!$N$5:$N$14971,'Tasks 1,2'!R$10,'Al Bundy'!$D$5:$D$14971,"United States") -> 8 | S16: =COUNTIFS('Al Bundy'!$G$5:$G$14971,"Male",'Al Bundy'!$H$5:$H$14971,'Tasks 1,2'!$B16,'Al Bundy'!$M$5:$M$14971,"2016",'Al Bundy'!$N$5:$N$14971,'Tasks 1,2'!S$10,'Al Bundy'!$D$5:$D$14971,"United States") -> 8 | T16: =COUNTIFS('Al Bundy'!$G$5:$G$14971,"Male",'Al Bundy'!$H$5:$H$14971,'Tasks 1,2'!$B16,'Al Bundy'!$M$5:$M$14971,"2016",'Al Bundy'!$N$5:$N$14971,'Tasks 1,2'!T$10,'Al Bundy'!$D$5:$D$14971,"United States") -> 15 | U16: =COUNTIFS('Al Bundy'!$G$5:$G$14971,"Male",'Al Bundy'!$H$5:$H$14971,'Tasks 1,2'!$B16,'Al Bundy'!$M$5:$M$14971,"2016",'Al Bundy'!$N$5:$N$14971,'Tasks 1,2'!U$10,'Al Bundy'!$D$5:$D$14971,"United States") -> 9 | V16: =COUNTIFS('Al Bundy'!$G$5:$G$14971,"Male",'Al Bundy'!$H$5:$H$14971,'Tasks 1,2'!$B16,'Al Bundy'!$M$5:$M$14971,"2016",'Al Bundy'!$N$5:$N$14971,'Tasks 1,2'!V$10,'Al Bundy'!$D$5:$D$14971,"United States") -> 17 | W16: =COUNTIFS('Al Bundy'!$G$5:$G$14971,"Male",'Al Bundy'!$H$5:$H$14971,'Tasks 1,2'!$B16,'Al Bundy'!$M$5:$M$14971,"2016",'Al Bundy'!$N$5:$N$14971,'Tasks 1,2'!W$10,'Al Bundy'!$D$5:$D$14971,"United States") -> 17 | ... AA16: =COUNTIFS('Al Bundy'!$G$5:$G$14971,"Male",'Al Bundy'!$H$5:$H$14971,'Tasks 1,2'!$B16,'Al Bundy'!$M$5:$M$14971,"2016",'Al Bundy'!$N$5:$N$14971,'Tasks 1,2'!AA$10,'Al Bundy'!$D$5:$D$14971,"United States") -> 6 | AC16: =AVERAGE(C16:AA16) -> 7.875 | AE16: =_xlfn.STDEV.S(C16:AA16)/SQRT($AJ$31) -> 0.94468862 | AG16: =AE16*$AJ$32 -> 1.9545608 | AI16: =AC16-AG16 -> 5.9204392 | AJ16: =AC16+AG16 -> 9.8295608 | AL16: =ROUND(AJ16,0) -> 10 | AN16: =ROUNDUP(AJ16,0) -> 10 | AP16: 13.195407 | AR16: =AP16-AL16 -> 3.1954067
B17: 9 | C17: =COUNTIFS('Al Bundy'!$G$5:$G$14971,"Male",'Al Bundy'!$H$5:$H$14971,'Tasks 1,2'!$B17,'Al Bundy'!$M$5:$M$14971,"2015",'Al Bundy'!$N$5:$N$14971,'Tasks 1,2'!C$10,'Al Bundy'!$D$5:$D$14971,"United States") -> 10 | D17: =COUNTIFS('Al Bundy'!$G$5:$G$14971,"Male",'Al Bundy'!$H$5:$H$14971,'Tasks 1,2'!$B17,'Al Bundy'!$M$5:$M$14971,"2015",'Al Bundy'!$N$5:$N$14971,'Tasks 1,2'!D$10,'Al Bundy'!$D$5:$D$14971,"United States") -> 14 | E17: =COUNTIFS('Al Bundy'!$G$5:$G$14971,"Male",'Al Bundy'!$H$5:$H$14971,'Tasks 1,2'!$B17,'Al Bundy'!$M$5:$M$14971,"2015",'Al Bundy'!$N$5:$N$14971,'Tasks 1,2'!E$10,'Al Bundy'!$D$5:$D$14971,"United States") -> 7 | F17: =COUNTIFS('Al Bundy'!$G$5:$G$14971,"Male",'Al Bundy'!$H$5:$H$14971,'Tasks 1,2'!$B17,'Al Bundy'!$M$5:$M$14971,"2015",'Al Bundy'!$N$5:$N$14971,'Tasks 1,2'!F$10,'Al Bundy'!$D$5:$D$14971,"United States") -> 9 | G17: =COUNTIFS('Al Bundy'!$G$5:$G$14971,"Male",'Al Bundy'!$H$5:$H$14971,'Tasks 1,2'!$B17,'Al Bundy'!$M$5:$M$14971,"2015",'Al Bundy'!$N$5:$N$14971,'Tasks 1,2'!G$10,'Al Bundy'!$D$5:$D$14971,"United States") -> 17 | H17: =COUNTIFS('Al Bundy'!$G$5:$G$14971,"Male",'Al Bundy'!$H$5:$H$14971,'Tasks 1,2'!$B17,'Al Bundy'!$M$5:$M$14971,"2015",'Al Bundy'!$N$5:$N$14971,'Tasks 1,2'!H$10,'Al Bundy'!$D$5:$D$14971,"United States") -> 16 | I17: =COUNTIFS('Al Bundy'!$G$5:$G$14971,"Male",'Al Bundy'!$H$5:$H$14971,'Tasks 1,2'!$B17,'Al Bundy'!$M$5:$M$14971,"2015",'Al Bundy'!$N$5:$N$14971,'Tasks 1,2'!I$10,'Al Bundy'!$D$5:$D$14971,"United States") -> 20 | J17: =COUNTIFS('Al Bundy'!$G$5:$G$14971,"Male",'Al Bundy'!$H$5:$H$14971,'Tasks 1,2'!$B17,'Al Bundy'!$M$5:$M$14971,"2015",'Al Bundy'!$N$5:$N$14971,'Tasks 1,2'!J$10,'Al Bundy'!$D$5:$D$14971,"United States") -> 21 | ... N17: =COUNTIFS('Al Bundy'!$G$5:$G$14971,"Male",'Al Bundy'!$H$5:$H$14971,'Tasks 1,2'!$B17,'Al Bundy'!$M$5:$M$14971,"2015",'Al Bundy'!$N$5:$N$14971,'Tasks 1,2'!N$10,'Al Bundy'!$D$5:$D$14971,"United States") -> 12 | P17: =COUNTIFS('Al Bundy'!$G$5:$G$14971,"Male",'Al Bundy'!$H$5:$H$14971,'Tasks 1,2'!$B17,'Al Bundy'!$M$5:$M$14971,"2016",'Al Bundy'!$N$5:$N$14971,'Tasks 1,2'!P$10,'Al Bundy'!$D$5:$D$14971,"United States") -> 17 | Q17: =COUNTIFS('Al Bundy'!$G$5:$G$14971,"Male",'Al Bundy'!$H$5:$H$14971,'Tasks 1,2'!$B17,'Al Bundy'!$M$5:$M$14971,"2016",'Al Bundy'!$N$5:$N$14971,'Tasks 1,2'!Q$10,'Al Bundy'!$D$5:$D$14971,"United States") -> 13 | R17: =COUNTIFS('Al Bundy'!$G$5:$G$14971,"Male",'Al Bundy'!$H$5:$H$14971,'Tasks 1,2'!$B17,'Al Bundy'!$M$5:$M$14971,"2016",'Al Bundy'!$N$5:$N$14971,'Tasks 1,2'!R$10,'Al Bundy'!$D$5:$D$14971,"United States") -> 13 | S17: =COUNTIFS('Al Bundy'!$G$5:$G$14971,"Male",'Al Bundy'!$H$5:$H$14971,'Tasks 1,2'!$B17,'Al Bundy'!$M$5:$M$14971,"2016",'Al Bundy'!$N$5:$N$14971,'Tasks 1,2'!S$10,'Al Bundy'!$D$5:$D$14971,"United States") -> 11 | T17: =COUNTIFS('Al Bundy'!$G$5:$G$14971,"Male",'Al Bundy'!$H$5:$H$14971,'Tasks 1,2'!$B17,'Al Bundy'!$M$5:$M$14971,"2016",'Al Bundy'!$N$5:$N$14971,'Tasks 1,2'!T$10,'Al Bundy'!$D$5:$D$14971,"United States") -> 21 | U17: =COUNTIFS('Al Bundy'!$G$5:$G$14971,"Male",'Al Bundy'!$H$5:$H$14971,'Tasks 1,2'!$B17,'Al Bundy'!$M$5:$M$14971,"2016",'Al Bundy'!$N$5:$N$14971,'Tasks 1,2'!U$10,'Al Bundy'!$D$5:$D$14971,"United States") -> 22 | V17: =COUNTIFS('Al Bundy'!$G$5:$G$14971,"Male",'Al Bundy'!$H$5:$H$14971,'Tasks 1,2'!$B17,'Al Bundy'!$M$5:$M$14971,"2016",'Al Bundy'!$N$5:$N$14971,'Tasks 1,2'!V$10,'Al Bundy'!$D$5:$D$14971,"United States") -> 25 | W17: =COUNTIFS('Al Bundy'!$G$5:$G$14971,"Male",'Al Bundy'!$H$5:$H$14971,'Tasks 1,2'!$B17,'Al Bundy'!$M$5:$M$14971,"2016",'Al Bundy'!$N$5:$N$14971,'Tasks 1,2'!W$10,'Al Bundy'!$D$5:$D$14971,"United States") -> 30 | ... AA17: =COUNTIFS('Al Bundy'!$G$5:$G$14971,"Male",'Al Bundy'!$H$5:$H$14971,'Tasks 1,2'!$B17,'Al Bundy'!$M$5:$M$14971,"2016",'Al Bundy'!$N$5:$N$14971,'Tasks 1,2'!AA$10,'Al Bundy'!$D$5:$D$14971,"United States") -> 10 | AC17: =AVERAGE(C17:AA17) -> 16.333333 | AE17: =_xlfn.STDEV.S(C17:AA17)/SQRT($AJ$31) -> 1.2621391 | AG17: =AE17*$AJ$32 -> 2.6113658 | AI17: =AC17-AG17 -> 13.721967 | AJ17: =AC17+AG17 -> 18.944699 | AL17: =ROUND(AJ17,0) -> 19 | AN17: =ROUNDUP(AJ17,0) -> 19 | AP17: 23.123398 | AR17: =AP17-AL17 -> 4.1233979
B18: 9.5 | C18: =COUNTIFS('Al Bundy'!$G$5:$G$14971,"Male",'Al Bundy'!$H$5:$H$14971,'Tasks 1,2'!$B18,'Al Bundy'!$M$5:$M$14971,"2015",'Al Bundy'!$N$5:$N$14971,'Tasks 1,2'!C$10,'Al Bundy'!$D$5:$D$14971,"United States") -> 18 | D18: =COUNTIFS('Al Bundy'!$G$5:$G$14971,"Male",'Al Bundy'!$H$5:$H$14971,'Tasks 1,2'!$B18,'Al Bundy'!$M$5:$M$14971,"2015",'Al Bundy'!$N$5:$N$14971,'Tasks 1,2'!D$10,'Al Bundy'!$D$5:$D$14971,"United States") -> 16 | E18: =COUNTIFS('Al Bundy'!$G$5:$G$14971,"Male",'Al Bundy'!$H$5:$H$14971,'Tasks 1,2'!$B18,'Al Bundy'!$M$5:$M$14971,"2015",'Al Bundy'!$N$5:$N$14971,'Tasks 1,2'!E$10,'Al Bundy'!$D$5:$D$14971,"United States") -> 23 | F18: =COUNTIFS('Al Bundy'!$G$5:$G$14971,"Male",'Al Bundy'!$H$5:$H$14971,'Tasks 1,2'!$B18,'Al Bundy'!$M$5:$M$14971,"2015",'Al Bundy'!$N$5:$N$14971,'Tasks 1,2'!F$10,'Al Bundy'!$D$5:$D$14971,"United States") -> 15 | G18: =COUNTIFS('Al Bundy'!$G$5:$G$14971,"Male",'Al Bundy'!$H$5:$H$14971,'Tasks 1,2'!$B18,'Al Bundy'!$M$5:$M$14971,"2015",'Al Bundy'!$N$5:$N$14971,'Tasks 1,2'!G$10,'Al Bundy'!$D$5:$D$14971,"United States") -> 16 | H18: =COUNTIFS('Al Bundy'!$G$5:$G$14971,"Male",'Al Bundy'!$H$5:$H$14971,'Tasks 1,2'!$B18,'Al Bundy'!$M$5:$M$14971,"2015",'Al Bundy'!$N$5:$N$14971,'Tasks 1,2'!H$10,'Al Bundy'!$D$5:$D$14971,"United States") -> 16 | I18: =COUNTIFS('Al Bundy'!$G$5:$G$14971,"Male",'Al Bundy'!$H$5:$H$14971,'Tasks 1,2'!$B18,'Al Bundy'!$M$5:$M$14971,"2015",'Al Bundy'!$N$5:$N$14971,'Tasks 1,2'!I$10,'Al Bundy'!$D$5:$D$14971,"United States") -> 19 | J18: =COUNTIFS('Al Bundy'!$G$5:$G$14971,"Male",'Al Bundy'!$H$5:$H$14971,'Tasks 1,2'!$B18,'Al Bundy'!$M$5:$M$14971,"2015",'Al Bundy'!$N$5:$N$14971,'Tasks 1,2'!J$10,'Al Bundy'!$D$5:$D$14971,"United States") -> 26 | ... N18: =COUNTIFS('Al Bundy'!$G$5:$G$14971,"Male",'Al Bundy'!$H$5:$H$14971,'Tasks 1,2'!$B18,'Al Bundy'!$M$5:$M$14971,"2015",'Al Bundy'!$N$5:$N$14971,'Tasks 1,2'!N$10,'Al Bundy'!$D$5:$D$14971,"United States") -> 24 | P18: =COUNTIFS('Al Bundy'!$G$5:$G$14971,"Male",'Al Bundy'!$H$5:$H$14971,'Tasks 1,2'!$B18,'Al Bundy'!$M$5:$M$14971,"2016",'Al Bundy'!$N$5:$N$14971,'Tasks 1,2'!P$10,'Al Bundy'!$D$5:$D$14971,"United States") -> 19 | Q18: =COUNTIFS('Al Bundy'!$G$5:$G$14971,"Male",'Al Bundy'!$H$5:$H$14971,'Tasks 1,2'!$B18,'Al Bundy'!$M$5:$M$14971,"2016",'Al Bundy'!$N$5:$N$14971,'Tasks 1,2'!Q$10,'Al Bundy'!$D$5:$D$14971,"United States") -> 25 | R18: =COUNTIFS('Al Bundy'!$G$5:$G$14971,"Male",'Al Bundy'!$H$5:$H$14971,'Tasks 1,2'!$B18,'Al Bundy'!$M$5:$M$14971,"2016",'Al Bundy'!$N$5:$N$14971,'Tasks 1,2'!R$10,'Al Bundy'!$D$5:$D$14971,"United States") -> 27 | S18: =COUNTIFS('Al Bundy'!$G$5:$G$14971,"Male",'Al Bundy'!$H$5:$H$14971,'Tasks 1,2'!$B18,'Al Bundy'!$M$5:$M$14971,"2016",'Al Bundy'!$N$5:$N$14971,'Tasks 1,2'!S$10,'Al Bundy'!$D$5:$D$14971,"United States") -> 24 | T18: =COUNTIFS('Al Bundy'!$G$5:$G$14971,"Male",'Al Bundy'!$H$5:$H$14971,'Tasks 1,2'!$B18,'Al Bundy'!$M$5:$M$14971,"2016",'Al Bundy'!$N$5:$N$14971,'Tasks 1,2'!T$10,'Al Bundy'!$D$5:$D$14971,"United States") -> 26 | U18: =COUNTIFS('Al Bundy'!$G$5:$G$14971,"Male",'Al Bundy'!$H$5:$H$14971,'Tasks 1,2'!$B18,'Al Bundy'!$M$5:$M$14971,"2016",'Al Bundy'!$N$5:$N$14971,'Tasks 1,2'!U$10,'Al Bundy'!$D$5:$D$14971,"United States") -> 33 | V18: =COUNTIFS('Al Bundy'!$G$5:$G$14971,"Male",'Al Bundy'!$H$5:$H$14971,'Tasks 1,2'!$B18,'Al Bundy'!$M$5:$M$14971,"2016",'Al Bundy'!$N$5:$N$14971,'Tasks 1,2'!V$10,'Al Bundy'!$D$5:$D$14971,"United States") -> 25 | W18: =COUNTIFS('Al Bundy'!$G$5:$G$14971,"Male",'Al Bundy'!$H$5:$H$14971,'Tasks 1,2'!$B18,'Al Bundy'!$M$5:$M$14971,"2016",'Al Bundy'!$N$5:$N$14971,'Tasks 1,2'!W$10,'Al Bundy'!$D$5:$D$14971,"United States") -> 47 | ... AA18: =COUNTIFS('Al Bundy'!$G$5:$G$14971,"Male",'Al Bundy'!$H$5:$H$14971,'Tasks 1,2'!$B18,'Al Bundy'!$M$5:$M$14971,"2016",'Al Bundy'!$N$5:$N$14971,'Tasks 1,2'!AA$10,'Al Bundy'!$D$5:$D$14971,"United States") -> 26 | AC18: =AVERAGE(C18:AA18) -> 25.583333 | AE18: =_xlfn.STDEV.S(C18:AA18)/SQRT($AJ$31) -> 1.7661436 | AG18: =AE18*$AJ$32 -> 3.6541511 | AI18: =AC18-AG18 -> 21.929182 | AJ18: =AC18+AG18 -> 29.237484 | AL18: =ROUND(AJ18,0) -> 29 | AN18: =ROUNDUP(AJ18,0) -> 30 | AP18: 35.666277 | AR18: =AP18-AL18 -> 6.6662768
B19: 10 | C19: =COUNTIFS('Al Bundy'!$G$5:$G$14971,"Male",'Al Bundy'!$H$5:$H$14971,'Tasks 1,2'!$B19,'Al Bundy'!$M$5:$M$14971,"2015",'Al Bundy'!$N$5:$N$14971,'Tasks 1,2'!C$10,'Al Bundy'!$D$5:$D$14971,"United States") -> 8 | D19: =COUNTIFS('Al Bundy'!$G$5:$G$14971,"Male",'Al Bundy'!$H$5:$H$14971,'Tasks 1,2'!$B19,'Al Bundy'!$M$5:$M$14971,"2015",'Al Bundy'!$N$5:$N$14971,'Tasks 1,2'!D$10,'Al Bundy'!$D$5:$D$14971,"United States") -> 13 | E19: =COUNTIFS('Al Bundy'!$G$5:$G$14971,"Male",'Al Bundy'!$H$5:$H$14971,'Tasks 1,2'!$B19,'Al Bundy'!$M$5:$M$14971,"2015",'Al Bundy'!$N$5:$N$14971,'Tasks 1,2'!E$10,'Al Bundy'!$D$5:$D$14971,"United States") -> 13 | F19: =COUNTIFS('Al Bundy'!$G$5:$G$14971,"Male",'Al Bundy'!$H$5:$H$14971,'Tasks 1,2'!$B19,'Al Bundy'!$M$5:$M$14971,"2015",'Al Bundy'!$N$5:$N$14971,'Tasks 1,2'!F$10,'Al Bundy'!$D$5:$D$14971,"United States") -> 15 | G19: =COUNTIFS('Al Bundy'!$G$5:$G$14971,"Male",'Al Bundy'!$H$5:$H$14971,'Tasks 1,2'!$B19,'Al Bundy'!$M$5:$M$14971,"2015",'Al Bundy'!$N$5:$N$14971,'Tasks 1,2'!G$10,'Al Bundy'!$D$5:$D$14971,"United States") -> 7 | H19: =COUNTIFS('Al Bundy'!$G$5:$G$14971,"Male",'Al Bundy'!$H$5:$H$14971,'Tasks 1,2'!$B19,'Al Bundy'!$M$5:$M$14971,"2015",'Al Bundy'!$N$5:$N$14971,'Tasks 1,2'!H$10,'Al Bundy'!$D$5:$D$14971,"United States") -> 20 | I19: =COUNTIFS('Al Bundy'!$G$5:$G$14971,"Male",'Al Bundy'!$H$5:$H$14971,'Tasks 1,2'!$B19,'Al Bundy'!$M$5:$M$14971,"2015",'Al Bundy'!$N$5:$N$14971,'Tasks 1,2'!I$10,'Al Bundy'!$D$5:$D$14971,"United States") -> 22 | J19: =COUNTIFS('Al Bundy'!$G$5:$G$14971,"Male",'Al Bundy'!$H$5:$H$14971,'Tasks 1,2'!$B19,'Al Bundy'!$M$5:$M$14971,"2015",'Al Bundy'!$N$5:$N$14971,'Tasks 1,2'!J$10,'Al Bundy'!$D$5:$D$14971,"United States") -> 18 | ... N19: =COUNTIFS('Al Bundy'!$G$5:$G$14971,"Male",'Al Bundy'!$H$5:$H$14971,'Tasks 1,2'!$B19,'Al Bundy'!$M$5:$M$14971,"2015",'Al Bundy'!$N$5:$N$14971,'Tasks 1,2'!N$10,'Al Bundy'!$D$5:$D$14971,"United States") -> 14 | P19: =COUNTIFS('Al Bundy'!$G$5:$G$14971,"Male",'Al Bundy'!$H$5:$H$14971,'Tasks 1,2'!$B19,'Al Bundy'!$M$5:$M$14971,"2016",'Al Bundy'!$N$5:$N$14971,'Tasks 1,2'!P$10,'Al Bundy'!$D$5:$D$14971,"United States") -> 17 | Q19: =COUNTIFS('Al Bundy'!$G$5:$G$14971,"Male",'Al Bundy'!$H$5:$H$14971,'Tasks 1,2'!$B19,'Al Bundy'!$M$5:$M$14971,"2016",'Al Bundy'!$N$5:$N$14971,'Tasks 1,2'!Q$10,'Al Bundy'!$D$5:$D$14971,"United States") -> 26 | R19: =COUNTIFS('Al Bundy'!$G$5:$G$14971,"Male",'Al Bundy'!$H$5:$H$14971,'Tasks 1,2'!$B19,'Al Bundy'!$M$5:$M$14971,"2016",'Al Bundy'!$N$5:$N$14971,'Tasks 1,2'!R$10,'Al Bundy'!$D$5:$D$14971,"United States") -> 26 | S19: =COUNTIFS('Al Bundy'!$G$5:$G$14971,"Male",'Al Bundy'!$H$5:$H$14971,'Tasks 1,2'!$B19,'Al Bundy'!$M$5:$M$14971,"2016",'Al Bundy'!$N$5:$N$14971,'Tasks 1,2'!S$10,'Al Bundy'!$D$5:$D$14971,"United States") -> 19 | T19: =COUNTIFS('Al Bundy'!$G$5:$G$14971,"Male",'Al Bundy'!$H$5:$H$14971,'Tasks 1,2'!$B19,'Al Bundy'!$M$5:$M$14971,"2016",'Al Bundy'!$N$5:$N$14971,'Tasks 1,2'!T$10,'Al Bundy'!$D$5:$D$14971,"United States") -> 16 | U19: =COUNTIFS('Al Bundy'!$G$5:$G$14971,"Male",'Al Bundy'!$H$5:$H$14971,'Tasks 1,2'!$B19,'Al Bundy'!$M$5:$M$14971,"2016",'Al Bundy'!$N$5:$N$14971,'Tasks 1,2'!U$10,'Al Bundy'!$D$5:$D$14971,"United States") -> 31 | V19: =COUNTIFS('Al Bundy'!$G$5:$G$14971,"Male",'Al Bundy'!$H$5:$H$14971,'Tasks 1,2'!$B19,'Al Bundy'!$M$5:$M$14971,"2016",'Al Bundy'!$N$5:$N$14971,'Tasks 1,2'!V$10,'Al Bundy'!$D$5:$D$14971,"United States") -> 25 | W19: =COUNTIFS('Al Bundy'!$G$5:$G$14971,"Male",'Al Bundy'!$H$5:$H$14971,'Tasks 1,2'!$B19,'Al Bundy'!$M$5:$M$14971,"2016",'Al Bundy'!$N$5:$N$14971,'Tasks 1,2'!W$10,'Al Bundy'!$D$5:$D$14971,"United States") -> 24 | ... AA19: =COUNTIFS('Al Bundy'!$G$5:$G$14971,"Male",'Al Bundy'!$H$5:$H$14971,'Tasks 1,2'!$B19,'Al Bundy'!$M$5:$M$14971,"2016",'Al Bundy'!$N$5:$N$14971,'Tasks 1,2'!AA$10,'Al Bundy'!$D$5:$D$14971,"United States") -> 20 | AC19: =AVERAGE(C19:AA19) -> 18.791667 | AE19: =_xlfn.STDEV.S(C19:AA19)/SQRT($AJ$31) -> 1.3255832 | AG19: =AE19*$AJ$32 -> 2.7426317 | AI19: =AC19-AG19 -> 16.049035 | AJ19: =AC19+AG19 -> 21.534298 | AL19: =ROUND(AJ19,0) -> 22 | AN19: =ROUNDUP(AJ19,0) -> 22 | AP19: 26.165154 | AR19: =AP19-AL19 -> 4.1651537
B20: 10.5 | C20: =COUNTIFS('Al Bundy'!$G$5:$G$14971,"Male",'Al Bundy'!$H$5:$H$14971,'Tasks 1,2'!$B20,'Al Bundy'!$M$5:$M$14971,"2015",'Al Bundy'!$N$5:$N$14971,'Tasks 1,2'!C$10,'Al Bundy'!$D$5:$D$14971,"United States") -> 7 | D20: =COUNTIFS('Al Bundy'!$G$5:$G$14971,"Male",'Al Bundy'!$H$5:$H$14971,'Tasks 1,2'!$B20,'Al Bundy'!$M$5:$M$14971,"2015",'Al Bundy'!$N$5:$N$14971,'Tasks 1,2'!D$10,'Al Bundy'!$D$5:$D$14971,"United States") -> 13 | E20: =COUNTIFS('Al Bundy'!$G$5:$G$14971,"Male",'Al Bundy'!$H$5:$H$14971,'Tasks 1,2'!$B20,'Al Bundy'!$M$5:$M$14971,"2015",'Al Bundy'!$N$5:$N$14971,'Tasks 1,2'!E$10,'Al Bundy'!$D$5:$D$14971,"United States") -> 8 | F20: =COUNTIFS('Al Bundy'!$G$5:$G$14971,"Male",'Al Bundy'!$H$5:$H$14971,'Tasks 1,2'!$B20,'Al Bundy'!$M$5:$M$14971,"2015",'Al Bundy'!$N$5:$N$14971,'Tasks 1,2'!F$10,'Al Bundy'!$D$5:$D$14971,"United States") -> 8 | G20: =COUNTIFS('Al Bundy'!$G$5:$G$14971,"Male",'Al Bundy'!$H$5:$H$14971,'Tasks 1,2'!$B20,'Al Bundy'!$M$5:$M$14971,"2015",'Al Bundy'!$N$5:$N$14971,'Tasks 1,2'!G$10,'Al Bundy'!$D$5:$D$14971,"United States") -> 15 | H20: =COUNTIFS('Al Bundy'!$G$5:$G$14971,"Male",'Al Bundy'!$H$5:$H$14971,'Tasks 1,2'!$B20,'Al Bundy'!$M$5:$M$14971,"2015",'Al Bundy'!$N$5:$N$14971,'Tasks 1,2'!H$10,'Al Bundy'!$D$5:$D$14971,"United States") -> 10 | I20: =COUNTIFS('Al Bundy'!$G$5:$G$14971,"Male",'Al Bundy'!$H$5:$H$14971,'Tasks 1,2'!$B20,'Al Bundy'!$M$5:$M$14971,"2015",'Al Bundy'!$N$5:$N$14971,'Tasks 1,2'!I$10,'Al Bundy'!$D$5:$D$14971,"United States") -> 16 | J20: =COUNTIFS('Al Bundy'!$G$5:$G$14971,"Male",'Al Bundy'!$H$5:$H$14971,'Tasks 1,2'!$B20,'Al Bundy'!$M$5:$M$14971,"2015",'Al Bundy'!$N$5:$N$14971,'Tasks 1,2'!J$10,'Al Bundy'!$D$5:$D$14971,"United States") -> 8 | ... N20: =COUNTIFS('Al Bundy'!$G$5:$G$14971,"Male",'Al Bundy'!$H$5:$H$14971,'Tasks 1,2'!$B20,'Al Bundy'!$M$5:$M$14971,"2015",'Al Bundy'!$N$5:$N$14971,'Tasks 1,2'!N$10,'Al Bundy'!$D$5:$D$14971,"United States") -> 14 | P20: =COUNTIFS('Al Bundy'!$G$5:$G$14971,"Male",'Al Bundy'!$H$5:$H$14971,'Tasks 1,2'!$B20,'Al Bundy'!$M$5:$M$14971,"2016",'Al Bundy'!$N$5:$N$14971,'Tasks 1,2'!P$10,'Al Bundy'!$D$5:$D$14971,"United States") -> 13 | Q20: =COUNTIFS('Al Bundy'!$G$5:$G$14971,"Male",'Al Bundy'!$H$5:$H$14971,'Tasks 1,2'!$B20,'Al Bundy'!$M$5:$M$14971,"2016",'Al Bundy'!$N$5:$N$14971,'Tasks 1,2'!Q$10,'Al Bundy'!$D$5:$D$14971,"United States") -> 16 | R20: =COUNTIFS('Al Bundy'!$G$5:$G$14971,"Male",'Al Bundy'!$H$5:$H$14971,'Tasks 1,2'!$B20,'Al Bundy'!$M$5:$M$14971,"2016",'Al Bundy'!$N$5:$N$14971,'Tasks 1,2'!R$10,'Al Bundy'!$D$5:$D$14971,"United States") -> 22 | S20: =COUNTIFS('Al Bundy'!$G$5:$G$14971,"Male",'Al Bundy'!$H$5:$H$14971,'Tasks 1,2'!$B20,'Al Bundy'!$M$5:$M$14971,"2016",'Al Bundy'!$N$5:$N$14971,'Tasks 1,2'!S$10,'Al Bundy'!$D$5:$D$14971,"United States") -> 14 | T20: =COUNTIFS('Al Bundy'!$G$5:$G$14971,"Male",'Al Bundy'!$H$5:$H$14971,'Tasks 1,2'!$B20,'Al Bundy'!$M$5:$M$14971,"2016",'Al Bundy'!$N$5:$N$14971,'Tasks 1,2'!T$10,'Al Bundy'!$D$5:$D$14971,"United States") -> 28 | U20: =COUNTIFS('Al Bundy'!$G$5:$G$14971,"Male",'Al Bundy'!$H$5:$H$14971,'Tasks 1,2'!$B20,'Al Bundy'!$M$5:$M$14971,"2016",'Al Bundy'!$N$5:$N$14971,'Tasks 1,2'!U$10,'Al Bundy'!$D$5:$D$14971,"United States") -> 19 | V20: =COUNTIFS('Al Bundy'!$G$5:$G$14971,"Male",'Al Bundy'!$H$5:$H$14971,'Tasks 1,2'!$B20,'Al Bundy'!$M$5:$M$14971,"2016",'Al Bundy'!$N$5:$N$14971,'Tasks 1,2'!V$10,'Al Bundy'!$D$5:$D$14971,"United States") -> 18 | W20: =COUNTIFS('Al Bundy'!$G$5:$G$14971,"Male",'Al Bundy'!$H$5:$H$14971,'Tasks 1,2'!$B20,'Al Bundy'!$M$5:$M$14971,"2016",'Al Bundy'!$N$5:$N$14971,'Tasks 1,2'!W$10,'Al Bundy'!$D$5:$D$14971,"United States") -> 15 | ... AA20: =COUNTIFS('Al Bundy'!$G$5:$G$14971,"Male",'Al Bundy'!$H$5:$H$14971,'Tasks 1,2'!$B20,'Al Bundy'!$M$5:$M$14971,"2016",'Al Bundy'!$N$5:$N$14971,'Tasks 1,2'!AA$10,'Al Bundy'!$D$5:$D$14971,"United States") -> 10 | AC20: =AVERAGE(C20:AA20) -> 14.958333 | AE20: =_xlfn.STDEV.S(C20:AA20)/SQRT($AJ$31) -> 1.0205837 | AG20: =AE20*$AJ$32 -> 2.1115878 | AI20: =AC20-AG20 -> 12.846746 | AJ20: =AC20+AG20 -> 17.069921 | AL20: =ROUND(AJ20,0) -> 17 | AN20: =ROUNDUP(AJ20,0) -> 18 | AP20: 20.563534 | AR20: =AP20-AL20 -> 3.5635337
