Workbook
Name Slicer_Host1: #N/A
Name Slicer_Year: #N/A

Sheet survey
A1: Timestamp | B1: Which country are you from? | C1: What is your gender? | D1: Trim_Gender | E1: Proper_Gender | F1: Left_gender | G1: Gender | H1: age | I1: age_bracket | J1: Which country is your favorite in ongoing FIFA worldcup? | K1: Which country do you think will win? | L1: What is your name (nickname) ? I will use it to call you in the class.
A2: 46221.547 | B2: India | C2: Female | D2: =TRIM(survey[[#This Row],[What is your gender?]]) -> Female | E2: =PROPER(survey[[#This Row],[Trim_Gender]]) -> Female | F2: =LEFT(survey[[#This Row],[Proper_Gender]],1) -> F | G2: =LEFT(PROPER(TRIM(survey[[#This Row],[What is your gender?]])),1) -> F | H2: 33 | I2: {=_xlfn.IFS(survey[[#This Row],[age]]< 25,"20-25",survey[[#This Row],[age]] <30,"25-30",survey[[#This Row],[age]]<35,"30-35",survey[[#This Row],[age]]<40,"35-40")} -> 30-35 | J2: None | K2: No idea | L2: Anitha
A3: 46221.548 | B3: Myanmar | C3: Female | D3: =TRIM(survey[[#This Row],[What is your gender?]]) -> Female | E3: =PROPER(survey[[#This Row],[Trim_Gender]]) -> Female | F3: =LEFT(survey[[#This Row],[Proper_Gender]],1) -> F | G3: =LEFT(PROPER(TRIM(survey[[#This Row],[What is your gender?]])),1) -> F | H3: 28 | I3: {=_xlfn.IFS(survey[[#This Row],[age]]< 25,"20-25",survey[[#This Row],[age]] <30,"25-30",survey[[#This Row],[age]]<35,"30-35",survey[[#This Row],[age]]<40,"35-40")} -> 25-30 | J3: Brazil | K3: Argentina | L3: Mihtet
A4: 46221.548 | B4: Myanmar | C4: Female | D4: =TRIM(survey[[#This Row],[What is your gender?]]) -> Female | E4: =PROPER(survey[[#This Row],[Trim_Gender]]) -> Female | F4: =LEFT(survey[[#This Row],[Proper_Gender]],1) -> F | G4: =LEFT(PROPER(TRIM(survey[[#This Row],[What is your gender?]])),1) -> F | H4: 39 | I4: {=_xlfn.IFS(survey[[#This Row],[age]]< 25,"20-25",survey[[#This Row],[age]] <30,"25-30",survey[[#This Row],[age]]<35,"30-35",survey[[#This Row],[age]]<40,"35-40")} -> 35-40 | J4: None | K4: Any Country | L4: Hnin Lae
A5: 46221.548 | B5: Nepal | C5: Female | D5: =TRIM(survey[[#This Row],[What is your gender?]]) -> Female | E5: =PROPER(survey[[#This Row],[Trim_Gender]]) -> Female | F5: =LEFT(survey[[#This Row],[Proper_Gender]],1) -> F | G5: =LEFT(PROPER(TRIM(survey[[#This Row],[What is your gender?]])),1) -> F | H5: 24 | I5: {=_xlfn.IFS(survey[[#This Row],[age]]< 25,"20-25",survey[[#This Row],[age]] <30,"25-30",survey[[#This Row],[age]]<35,"30-35",survey[[#This Row],[age]]<40,"35-40")} -> 20-25 | J5: Norway | K5: Spain | L5: Raisa | N5: Gender | O5: Count
A6: 46221.548 | B6: Myanmar | C6: Male | D6: =TRIM(survey[[#This Row],[What is your gender?]]) -> Male | E6: =PROPER(survey[[#This Row],[Trim_Gender]]) -> Male | F6: =LEFT(survey[[#This Row],[Proper_Gender]],1) -> M | G6: =LEFT(PROPER(TRIM(survey[[#This Row],[What is your gender?]])),1) -> M | H6: 27 | I6: {=_xlfn.IFS(survey[[#This Row],[age]]< 25,"20-25",survey[[#This Row],[age]] <30,"25-30",survey[[#This Row],[age]]<35,"30-35",survey[[#This Row],[age]]<40,"35-40")} -> 25-30 | J6: Brazil | K6: Brazil | L6: Kyaw Zin | N6: F | O6: =COUNTIF(survey[Gender], "F") -> 17
A7: 46221.548 | B7: Myanmar | C7: Male | D7: =TRIM(survey[[#This Row],[What is your gender?]]) -> Male | E7: =PROPER(survey[[#This Row],[Trim_Gender]]) -> Male | F7: =LEFT(survey[[#This Row],[Proper_Gender]],1) -> M | G7: =LEFT(PROPER(TRIM(survey[[#This Row],[What is your gender?]])),1) -> M | H7: 27 | I7: {=_xlfn.IFS(survey[[#This Row],[age]]< 25,"20-25",survey[[#This Row],[age]] <30,"25-30",survey[[#This Row],[age]]<35,"30-35",survey[[#This Row],[age]]<40,"35-40")} -> 25-30 | J7: Spain | K7: Spain | L7: Zaw | N7: M | O7: =COUNTIF(survey[Gender], "M") -> 9
A8: 46221.548 | B8: Vietnam | C8: Male | D8: =TRIM(survey[[#This Row],[What is your gender?]]) -> Male | E8: =PROPER(survey[[#This Row],[Trim_Gender]]) -> Male | F8: =LEFT(survey[[#This Row],[Proper_Gender]],1) -> M | G8: =LEFT(PROPER(TRIM(survey[[#This Row],[What is your gender?]])),1) -> M | H8: 23 | I8: {=_xlfn.IFS(survey[[#This Row],[age]]< 25,"20-25",survey[[#This Row],[age]] <30,"25-30",survey[[#This Row],[age]]<35,"30-35",survey[[#This Row],[age]]<40,"35-40")} -> 20-25 | J8: Argentina | K8: Suiiiiiiiii | L8: Kian | N8: Total | O8: =SUM(O6:O7) -> 26
A9: 46221.548 | B9: Myanmar | C9: Male | D9: =TRIM(survey[[#This Row],[What is your gender?]]) -> Male | E9: =PROPER(survey[[#This Row],[Trim_Gender]]) -> Male | F9: =LEFT(survey[[#This Row],[Proper_Gender]],1) -> M | G9: =LEFT(PROPER(TRIM(survey[[#This Row],[What is your gender?]])),1) -> M | H9: 26 | I9: {=_xlfn.IFS(survey[[#This Row],[age]]< 25,"20-25",survey[[#This Row],[age]] <30,"25-30",survey[[#This Row],[age]]<35,"30-35",survey[[#This Row],[age]]<40,"35-40")} -> 25-30 | J9: Norway | K9: Spain | L9: Parker
A10: 46221.549 | B10: Philippines | C10: Male | D10: =TRIM(survey[[#This Row],[What is your gender?]]) -> Male | E10: =PROPER(survey[[#This Row],[Trim_Gender]]) -> Male | F10: =LEFT(survey[[#This Row],[Proper_Gender]],1) -> M | G10: =LEFT(PROPER(TRIM(survey[[#This Row],[What is your gender?]])),1) -> M | H10: 37 | I10: {=_xlfn.IFS(survey[[#This Row],[age]]< 25,"20-25",survey[[#This Row],[age]] <30,"25-30",survey[[#This Row],[age]]<35,"30-35",survey[[#This Row],[age]]<40,"35-40")} -> 35-40 | J10: None | K10: Argentina maybe | L10: Mike
A11: 46221.549 | B11: Myanmar | C11: female | D11: =TRIM(survey[[#This Row],[What is your gender?]]) -> female | E11: =PROPER(survey[[#This Row],[Trim_Gender]]) -> Female | F11: =LEFT(survey[[#This Row],[Proper_Gender]],1) -> F | G11: =LEFT(PROPER(TRIM(survey[[#This Row],[What is your gender?]])),1) -> F | H11: 28 | I11: {=_xlfn.IFS(survey[[#This Row],[age]]< 25,"20-25",survey[[#This Row],[age]] <30,"25-30",survey[[#This Row],[age]]<35,"30-35",survey[[#This Row],[age]]<40,"35-40")} -> 25-30 | J11: Spain | K11: Spain | L11: Riley | N11: Age bracket | O11: Count
A12: 46221.549 | B12: Nepal | C12: Female | D12: =TRIM(survey[[#This Row],[What is your gender?]]) -> Female | E12: =PROPER(survey[[#This Row],[Trim_Gender]]) -> Female | F12: =LEFT(survey[[#This Row],[Proper_Gender]],1) -> F | G12: =LEFT(PROPER(TRIM(survey[[#This Row],[What is your gender?]])),1) -> F | H12: 23 | I12: {=_xlfn.IFS(survey[[#This Row],[age]]< 25,"20-25",survey[[#This Row],[age]] <30,"25-30",survey[[#This Row],[age]]<35,"30-35",survey[[#This Row],[age]]<40,"35-40")} -> 20-25 | J12: Argentina | K12: Argentina | L12: Khushi | N12: 20-25 | O12: =COUNTIF(survey[age_bracket], "20-25") -> 6
A13: 46221.549 | B13: Nepal | C13: Female | D13: =TRIM(survey[[#This Row],[What is your gender?]]) -> Female | E13: =PROPER(survey[[#This Row],[Trim_Gender]]) -> Female | F13: =LEFT(survey[[#This Row],[Proper_Gender]],1) -> F | G13: =LEFT(PROPER(TRIM(survey[[#This Row],[What is your gender?]])),1) -> F | H13: 24 | I13: {=_xlfn.IFS(survey[[#This Row],[age]]< 25,"20-25",survey[[#This Row],[age]] <30,"25-30",survey[[#This Row],[age]]<35,"30-35",survey[[#This Row],[age]]<40,"35-40")} -> 20-25 | J13: Argentina | K13: Argentina | L13: Nishma | N13: 25-30 | O13: =COUNTIF(survey[age_bracket], "25-30") -> 12
A14: 46221.549 | B14: Myanmar | C14: Female | D14: =TRIM(survey[[#This Row],[What is your gender?]]) -> Female | E14: =PROPER(survey[[#This Row],[Trim_Gender]]) -> Female | F14: =LEFT(survey[[#This Row],[Proper_Gender]],1) -> F | G14: =LEFT(PROPER(TRIM(survey[[#This Row],[What is your gender?]])),1) -> F | H14: 35 | I14: {=_xlfn.IFS(survey[[#This Row],[age]]< 25,"20-25",survey[[#This Row],[age]] <30,"25-30",survey[[#This Row],[age]]<35,"30-35",survey[[#This Row],[age]]<40,"35-40")} -> 35-40 | J14: Argentina | K14: Argentina | L14: Win | N14: 30-35 | O14: =COUNTIF(survey[age_bracket], "30-35") -> 5
A15: 46221.549 | B15: Nepal | C15: Male | D15: =TRIM(survey[[#This Row],[What is your gender?]]) -> Male | E15: =PROPER(survey[[#This Row],[Trim_Gender]]) -> Male | F15: =LEFT(survey[[#This Row],[Proper_Gender]],1) -> M | G15: =LEFT(PROPER(TRIM(survey[[#This Row],[What is your gender?]])),1) -> M | H15: 24 | I15: {=_xlfn.IFS(survey[[#This Row],[age]]< 25,"20-25",survey[[#This Row],[age]] <30,"25-30",survey[[#This Row],[age]]<35,"30-35",survey[[#This Row],[age]]<40,"35-40")} -> 20-25 | J15: Spain | K15: Spain | L15: Sovan | N15: 35-40 | O15: =COUNTIF(survey[age_bracket], "35-40") -> 3
A16: 46221.549 | B16: Thailand | C16: Female | D16: =TRIM(survey[[#This Row],[What is your gender?]]) -> Female | E16: =PROPER(survey[[#This Row],[Trim_Gender]]) -> Female | F16: =LEFT(survey[[#This Row],[Proper_Gender]],1) -> F | G16: =LEFT(PROPER(TRIM(survey[[#This Row],[What is your gender?]])),1) -> F | H16: 32 | I16: {=_xlfn.IFS(survey[[#This Row],[age]]< 25,"20-25",survey[[#This Row],[age]] <30,"25-30",survey[[#This Row],[age]]<35,"30-35",survey[[#This Row],[age]]<40,"35-40")} -> 30-35 | J16: None | K16: - | L16: Amm Wannarat | O16: =SUM(O12:O15) -> 26
A17: 46221.549 | B17: Bangladesh | C17: Male | D17: =TRIM(survey[[#This Row],[What is your gender?]]) -> Male | E17: =PROPER(survey[[#This Row],[Trim_Gender]]) -> Male | F17: =LEFT(survey[[#This Row],[Proper_Gender]],1) -> M | G17: =LEFT(PROPER(TRIM(survey[[#This Row],[What is your gender?]])),1) -> M | H17: 30 | I17: {=_xlfn.IFS(survey[[#This Row],[age]]< 25,"20-25",survey[[#This Row],[age]] <30,"25-30",survey[[#This Row],[age]]<35,"30-35",survey[[#This Row],[age]]<40,"35-40")} -> 30-35 | J17: Spain | K17: Argentina (RIGGED) | L17: Naseef
A18: 46221.549 | B18: Bangladesh | C18: female | D18: =TRIM(survey[[#This Row],[What is your gender?]]) -> female | E18: =PROPER(survey[[#This Row],[Trim_Gender]]) -> Female | F18: =LEFT(survey[[#This Row],[Proper_Gender]],1) -> F | G18: =LEFT(PROPER(TRIM(survey[[#This Row],[What is your gender?]])),1) -> F | H18: 25 | I18: {=_xlfn.IFS(survey[[#This Row],[age]]< 25,"20-25",survey[[#This Row],[age]] <30,"25-30",survey[[#This Row],[age]]<35,"30-35",survey[[#This Row],[age]]<40,"35-40")} -> 25-30 | J18: None | K18: Hopefully spain | L18: Rahma | N18: What is the count of females supporting Spain?
A19: 46221.549 | B19: Myanmar | C19: Female | D19: =TRIM(survey[[#This Row],[What is your gender?]]) -> Female | E19: =PROPER(survey[[#This Row],[Trim_Gender]]) -> Female | F19: =LEFT(survey[[#This Row],[Proper_Gender]],1) -> F | G19: =LEFT(PROPER(TRIM(survey[[#This Row],[What is your gender?]])),1) -> F | H19: 27 | I19: {=_xlfn.IFS(survey[[#This Row],[age]]< 25,"20-25",survey[[#This Row],[age]] <30,"25-30",survey[[#This Row],[age]]<35,"30-35",survey[[#This Row],[age]]<40,"35-40")} -> 25-30 | J19: None | L19: Shun Shun
A20: 46221.549 | B20: Bhutan | C20: Female | D20: =TRIM(survey[[#This Row],[What is your gender?]]) -> Female | E20: =PROPER(survey[[#This Row],[Trim_Gender]]) -> Female | F20: =LEFT(survey[[#This Row],[Proper_Gender]],1) -> F | G20: =LEFT(PROPER(TRIM(survey[[#This Row],[What is your gender?]])),1) -> F | H20: 31 | I20: {=_xlfn.IFS(survey[[#This Row],[age]]< 25,"20-25",survey[[#This Row],[age]] <30,"25-30",survey[[#This Row],[age]]<35,"30-35",survey[[#This Row],[age]]<40,"35-40")} -> 30-35 | J20: Spain | K20: Spain | L20: Tandin | O20: =COUNTIFS(survey[Gender],"F",survey[Which country is your favorite in ongoing FIFA worldcup?],"Spain") -> 2
A21: 46221.549 | B21: Thailand | C21: Male | D21: =TRIM(survey[[#This Row],[What is your gender?]]) -> Male | E21: =PROPER(survey[[#This Row],[Trim_Gender]]) -> Male | F21: =LEFT(survey[[#This Row],[Proper_Gender]],1) -> M | G21: =LEFT(PROPER(TRIM(survey[[#This Row],[What is your gender?]])),1) -> M | H21: 32 | I21: {=_xlfn.IFS(survey[[#This Row],[age]]< 25,"20-25",survey[[#This Row],[age]] <30,"25-30",survey[[#This Row],[age]]<35,"30-35",survey[[#This Row],[age]]<40,"35-40")} -> 30-35 | J21: England | K21: Argentina | L21: Bill
A22: 46221.549 | B22: Myanmar | C22: female | D22: =TRIM(survey[[#This Row],[What is your gender?]]) -> female | E22: =PROPER(survey[[#This Row],[Trim_Gender]]) -> Female | F22: =LEFT(survey[[#This Row],[Proper_Gender]],1) -> F | G22: =LEFT(PROPER(TRIM(survey[[#This Row],[What is your gender?]])),1) -> F | H22: 27 | I22: {=_xlfn.IFS(survey[[#This Row],[age]]< 25,"20-25",survey[[#This Row],[age]] <30,"25-30",survey[[#This Row],[age]]<35,"30-35",survey[[#This Row],[age]]<40,"35-40")} -> 25-30 | J22: Argentina | K22: Argentina | L22: Ying
A23: 46221.549 | B23: Nepal | C23: Female | D23: =TRIM(survey[[#This Row],[What is your gender?]]) -> Female | E23: =PROPER(survey[[#This Row],[Trim_Gender]]) -> Female | F23: =LEFT(survey[[#This Row],[Proper_Gender]],1) -> F | G23: =LEFT(PROPER(TRIM(survey[[#This Row],[What is your gender?]])),1) -> F | H23: 23 | I23: {=_xlfn.IFS(survey[[#This Row],[age]]< 25,"20-25",survey[[#This Row],[age]] <30,"25-30",survey[[#This Row],[age]]<35,"30-35",survey[[#This Row],[age]]<40,"35-40")} -> 20-25 | J23: Spain | K23: Spain | L23: Ranju
A24: 46221.549 | B24: Myanmar | C24: female | D24: =TRIM(survey[[#This Row],[What is your gender?]]) -> female | E24: =PROPER(survey[[#This Row],[Trim_Gender]]) -> Female | F24: =LEFT(survey[[#This Row],[Proper_Gender]],1) -> F | G24: =LEFT(PROPER(TRIM(survey[[#This Row],[What is your gender?]])),1) -> F | H24: 28 | I24: {=_xlfn.IFS(survey[[#This Row],[age]]< 25,"20-25",survey[[#This Row],[age]] <30,"25-30",survey[[#This Row],[age]]<35,"30-35",survey[[#This Row],[age]]<40,"35-40")} -> 25-30 | J24: None | K24: Argentina | L24: Thiri
A25: 46221.55 | B25: Nepal | C25: Male | D25: =TRIM(survey[[#This Row],[What is your gender?]]) -> Male | E25: =PROPER(survey[[#This Row],[Trim_Gender]]) -> Male | F25: =LEFT(survey[[#This Row],[Proper_Gender]],1) -> M | G25: =LEFT(PROPER(TRIM(survey[[#This Row],[What is your gender?]])),1) -> M | H25: 26 | I25: {=_xlfn.IFS(survey[[#This Row],[age]]< 25,"20-25",survey[[#This Row],[age]] <30,"25-30",survey[[#This Row],[age]]<35,"30-35",survey[[#This Row],[age]]<40,"35-40")} -> 25-30 | J25: Argentina | K25: Argentina | L25: Barun
A26: 46221.55 | B26: Myanmar | C26: Female | D26: =TRIM(survey[[#This Row],[What is your gender?]]) -> Female | E26: =PROPER(survey[[#This Row],[Trim_Gender]]) -> Female | F26: =LEFT(survey[[#This Row],[Proper_Gender]],1) -> F | G26: =LEFT(PROPER(TRIM(survey[[#This Row],[What is your gender?]])),1) -> F | H26: 29 | I26: {=_xlfn.IFS(survey[[#This Row],[age]]< 25,"20-25",survey[[#This Row],[age]] <30,"25-30",survey[[#This Row],[age]]<35,"30-35",survey[[#This Row],[age]]<40,"35-40")} -> 25-30 | J26: None | K26: Argentina | L26: Nwenny
A27: 46221.55 | B27: Nepal | C27: Female | D27: =TRIM(survey[[#This Row],[What is your gender?]]) -> Female | E27: =PROPER(survey[[#This Row],[Trim_Gender]]) -> Female | F27: =LEFT(survey[[#This Row],[Proper_Gender]],1) -> F | G27: =LEFT(PROPER(TRIM(survey[[#This Row],[What is your gender?]])),1) -> F | H27: 27 | I27: {=_xlfn.IFS(survey[[#This Row],[age]]< 25,"20-25",survey[[#This Row],[age]] <30,"25-30",survey[[#This Row],[age]]<35,"30-35",survey[[#This Row],[age]]<40,"35-40")} -> 25-30 | J27: None | K27: Argentina | L27: Neha

Sheet world_cup
A1: Year | B1: Host | C1: rank Xlookup | D1: rank Vloolup | E1: Teams | F1: Champion | G1: Runner-Up | H1: TopScorrer | I1: Attendance | J1: Propularity | K1: AttendanceAvg | L1: Matches
A2: 1930 | B2: Uruguay | C2: =IFERROR(_xlfn.XLOOKUP(world_cup[[#This Row],[Host]],fifa_ranking_2026_06_08[team],fifa_ranking_2026_06_08[2026_rank]),999) -> 16 | D2: =IFERROR(VLOOKUP(world_cup[[#This Row],[Host]],fifa_ranking_2026_06_08[[team]:[previous_rank]],4,FALSE),999) -> 16 | E2: 13 | F2: Uruguay | G2: Argentina | H2: Guillermo Stábile - 8 | I2: 590549 | J2: =world_cup[[#This Row],[Attendance]]/world_cup[[#This Row],[Teams]] -> 45426.846 | K2: 32808 | L2: 18
A3: 1934 | B3: Italy | C3: =IFERROR(_xlfn.XLOOKUP(world_cup[[#This Row],[Host]],fifa_ranking_2026_06_08[team],fifa_ranking_2026_06_08[2026_rank]),999) -> 12 | D3: =IFERROR(VLOOKUP(world_cup[[#This Row],[Host]],fifa_ranking_2026_06_08[[team]:[previous_rank]],4,FALSE),999) -> 12 | E3: 16 | F3: Italy | G3: Czechoslovakia | H3: Oldřich Nejedlý - 5 | I3: 363000 | J3: =world_cup[[#This Row],[Attendance]]/world_cup[[#This Row],[Teams]] -> 22687.5 | K3: 21353 | L3: 17
A4: 1938 | B4: France | C4: =IFERROR(_xlfn.XLOOKUP(world_cup[[#This Row],[Host]],fifa_ranking_2026_06_08[team],fifa_ranking_2026_06_08[2026_rank]),999) -> 3 | D4: =IFERROR(VLOOKUP(world_cup[[#This Row],[Host]],fifa_ranking_2026_06_08[[team]:[previous_rank]],4,FALSE),999) -> 3 | E4: 16 | F4: Italy | G4: Hungary | H4: Leônidas - 7 | I4: 375700 | J4: =world_cup[[#This Row],[Attendance]]/world_cup[[#This Row],[Teams]] -> 23481.25 | K4: 20872 | L4: 18
A5: 1950 | B5: Brazil | C5: =IFERROR(_xlfn.XLOOKUP(world_cup[[#This Row],[Host]],fifa_ranking_2026_06_08[team],fifa_ranking_2026_06_08[2026_rank]),999) -> 6 | D5: =IFERROR(VLOOKUP(world_cup[[#This Row],[Host]],fifa_ranking_2026_06_08[[team]:[previous_rank]],4,FALSE),999) -> 6 | E5: 15 | F5: Uruguay | G5: Brazil | H5: Ademir - 8 | I5: 1045246 | J5: =world_cup[[#This Row],[Attendance]]/world_cup[[#This Row],[Teams]] -> 69683.067 | K5: 47511 | L5: 22
A6: 1954 | B6: Switzerland | C6: =IFERROR(_xlfn.XLOOKUP(world_cup[[#This Row],[Host]],fifa_ranking_2026_06_08[team],fifa_ranking_2026_06_08[2026_rank]),999) -> 19 | D6: =IFERROR(VLOOKUP(world_cup[[#This Row],[Host]],fifa_ranking_2026_06_08[[team]:[previous_rank]],4,FALSE),999) -> 19 | E6: 16 | F6: Germany | G6: Hungary | H6: Sándor Kocsis - 11 | I6: 768607 | J6: =world_cup[[#This Row],[Attendance]]/world_cup[[#This Row],[Teams]] -> 48037.938 | K6: 29562 | L6: 26
A7: 1958 | B7: Sweden | C7: =IFERROR(_xlfn.XLOOKUP(world_cup[[#This Row],[Host]],fifa_ranking_2026_06_08[team],fifa_ranking_2026_06_08[2026_rank]),999) -> 38 | D7: =IFERROR(VLOOKUP(world_cup[[#This Row],[Host]],fifa_ranking_2026_06_08[[team]:[previous_rank]],4,FALSE),999) -> 38 | E7: 16 | F7: Brazil | G7: Sweden | H7: Just Fontaine - 13 | I7: 819810 | J7: =world_cup[[#This Row],[Attendance]]/world_cup[[#This Row],[Teams]] -> 51238.125 | K7: 23423 | L7: 35
A8: 1962 | B8: Chile | C8: =IFERROR(_xlfn.XLOOKUP(world_cup[[#This Row],[Host]],fifa_ranking_2026_06_08[team],fifa_ranking_2026_06_08[2026_rank]),999) -> 55 | D8: =IFERROR(VLOOKUP(world_cup[[#This Row],[Host]],fifa_ranking_2026_06_08[[team]:[previous_rank]],4,FALSE),999) -> 55 | E8: 16 | F8: Brazil | G8: Czechoslovakia | H8: Leonel Sánchez, Flórián Albert... - 4 | I8: 893172 | J8: =world_cup[[#This Row],[Attendance]]/world_cup[[#This Row],[Teams]] -> 55823.25 | K8: 27912 | L8: 32
A9: 1966 | B9: England | C9: =IFERROR(_xlfn.XLOOKUP(world_cup[[#This Row],[Host]],fifa_ranking_2026_06_08[team],fifa_ranking_2026_06_08[2026_rank]),999) -> 4 | D9: =IFERROR(VLOOKUP(world_cup[[#This Row],[Host]],fifa_ranking_2026_06_08[[team]:[previous_rank]],4,FALSE),999) -> 4 | E9: 16 | F9: England | G9: West Germany | H9: Eusébio - 9 | I9: 1563135 | J9: =world_cup[[#This Row],[Attendance]]/world_cup[[#This Row],[Teams]] -> 97695.938 | K9: 48848 | L9: 32
A10: 1970 | B10: Mexico | C10: =IFERROR(_xlfn.XLOOKUP(world_cup[[#This Row],[Host]],fifa_ranking_2026_06_08[team],fifa_ranking_2026_06_08[2026_rank]),999) -> 14 | D10: =IFERROR(VLOOKUP(world_cup[[#This Row],[Host]],fifa_ranking_2026_06_08[[team]:[previous_rank]],4,FALSE),999) -> 14 | E10: 16 | F10: Brazil | G10: Italy | H10: Gerd Müller - 10 | I10: 1603975 | J10: =world_cup[[#This Row],[Attendance]]/world_cup[[#This Row],[Teams]] -> 100248.44 | K10: 50124 | L10: 32
A11: 1974 | B11: Germany | C11: =IFERROR(_xlfn.XLOOKUP(world_cup[[#This Row],[Host]],fifa_ranking_2026_06_08[team],fifa_ranking_2026_06_08[2026_rank]),999) -> 10 | D11: =IFERROR(VLOOKUP(world_cup[[#This Row],[Host]],fifa_ranking_2026_06_08[[team]:[previous_rank]],4,FALSE),999) -> 10 | E11: 16 | F11: West Germany | G11: Netherlands | H11: Grzegorz Lato - 7 | I11: 1865753 | J11: =world_cup[[#This Row],[Attendance]]/world_cup[[#This Row],[Teams]] -> 116609.56 | K11: 49099 | L11: 38
A12: 1978 | B12: Argentina | C12: =IFERROR(_xlfn.XLOOKUP(world_cup[[#This Row],[Host]],fifa_ranking_2026_06_08[team],fifa_ranking_2026_06_08[2026_rank]),999) -> 1 | D12: =IFERROR(VLOOKUP(world_cup[[#This Row],[Host]],fifa_ranking_2026_06_08[[team]:[previous_rank]],4,FALSE),999) -> 1 | E12: 16 | F12: Argentina | G12: Netherlands | H12: Mario Kempes - 6 | I12: 1545791 | J12: =world_cup[[#This Row],[Attendance]]/world_cup[[#This Row],[Teams]] -> 96611.938 | K12: 40679 | L12: 38
A13: 1982 | B13: Spain | C13: =IFERROR(_xlfn.XLOOKUP(world_cup[[#This Row],[Host]],fifa_ranking_2026_06_08[team],fifa_ranking_2026_06_08[2026_rank]),999) -> 2 | D13: =IFERROR(VLOOKUP(world_cup[[#This Row],[Host]],fifa_ranking_2026_06_08[[team]:[previous_rank]],4,FALSE),999) -> 2 | E13: 24 | F13: Italy | G13: West Germany | H13: Paolo Rossi - 6 | I13: 2109723 | J13: =world_cup[[#This Row],[Attendance]]/world_cup[[#This Row],[Teams]] -> 87905.125 | K13: 40572 | L13: 52
... A23: 2022 | B23: Qatar | C23: =IFERROR(_xlfn.XLOOKUP(world_cup[[#This Row],[Host]],fifa_ranking_2026_06_08[team],fifa_ranking_2026_06_08[2026_rank]),999) -> 57 | D23: =IFERROR(VLOOKUP(world_cup[[#This Row],[Host]],fifa_ranking_2026_06_08[[team]:[previous_rank]],4,FALSE),999) -> 57 | E23: 32 | F23: Argentina | G23: France | H23: Kylian Mbappé - 8 | I23: 3404252 | J23: =world_cup[[#This Row],[Attendance]]/world_cup[[#This Row],[Teams]] -> 106382.88 | K23: 53191 | L23: 64

Sheet fifa_ranking_2026-06-08
A1: team | B1: team_code | C1: association | D1: 2026_rank | E1: 2022_rank | F1: improve_rank | G1: previous_rank | H1: points | I1: previous_points | J1: rated_matches
A2: Argentina | B2: ARG | C2: CONMEBOL | D2: 1 | E2: {=_xlfn.XLOOKUP(fifa_ranking_2026_06_08[[#This Row],[team]],fifa_ranking_2022_10_06[[#All],[team]],fifa_ranking_2022_10_06[[#All],[rank]])} -> 3 | F2: =fifa_ranking_2026_06_08[[#This Row],[2022_rank]]-fifa_ranking_2026_06_08[[#This Row],[2026_rank]] -> 2 | G2: 3 | H2: 1876.1183 | I2: 1874.8148 | J2: 59
A3: Spain | B3: ESP | C3: UEFA | D3: 2 | E3: {=_xlfn.XLOOKUP(fifa_ranking_2026_06_08[[#This Row],[team]],fifa_ranking_2022_10_06[[#All],[team]],fifa_ranking_2022_10_06[[#All],[rank]])} -> 7 | F3: =fifa_ranking_2026_06_08[[#This Row],[2022_rank]]-fifa_ranking_2026_06_08[[#This Row],[2026_rank]] -> 5 | G3: 2 | H3: 1873.0132 | I3: 1876.3952 | J3: 56
A4: France | B4: FRA | C4: UEFA | D4: 3 | E4: {=_xlfn.XLOOKUP(fifa_ranking_2026_06_08[[#This Row],[team]],fifa_ranking_2022_10_06[[#All],[team]],fifa_ranking_2022_10_06[[#All],[rank]])} -> 4 | F4: =fifa_ranking_2026_06_08[[#This Row],[2022_rank]]-fifa_ranking_2026_06_08[[#This Row],[2026_rank]] -> 1 | G4: 1 | H4: 1869.4284 | I4: 1877.3227 | J4: 57
A5: England | B5: ENG | C5: UEFA | D5: 4 | E5: {=_xlfn.XLOOKUP(fifa_ranking_2026_06_08[[#This Row],[team]],fifa_ranking_2022_10_06[[#All],[team]],fifa_ranking_2022_10_06[[#All],[rank]])} -> 5 | F5: =fifa_ranking_2026_06_08[[#This Row],[2022_rank]]-fifa_ranking_2026_06_08[[#This Row],[2026_rank]] -> 1 | G5: 4 | H5: 1827.0487 | I5: 1825.9655 | J5: 57
A6: Portugal | B6: POR | C6: UEFA | D6: 5 | E6: {=_xlfn.XLOOKUP(fifa_ranking_2026_06_08[[#This Row],[team]],fifa_ranking_2022_10_06[[#All],[team]],fifa_ranking_2022_10_06[[#All],[rank]])} -> 9 | F6: =fifa_ranking_2026_06_08[[#This Row],[2022_rank]]-fifa_ranking_2026_06_08[[#This Row],[2026_rank]] -> 4 | G6: 5 | H6: 1766.1775 | I6: 1763.8344 | J6: 56
A7: Brazil | B7: BRA | C7: CONMEBOL | D7: 6 | E7: {=_xlfn.XLOOKUP(fifa_ranking_2026_06_08[[#This Row],[team]],fifa_ranking_2022_10_06[[#All],[team]],fifa_ranking_2022_10_06[[#All],[rank]])} -> 1 | F7: =fifa_ranking_2026_06_08[[#This Row],[2022_rank]]-fifa_ranking_2026_06_08[[#This Row],[2026_rank]] -> -5 | G7: 6 | H7: 1765.8563 | I7: 1761.1609 | J7: 55
A8: Morocco | B8: MAR | C8: CAF | D8: 7 | E8: {=_xlfn.XLOOKUP(fifa_ranking_2026_06_08[[#This Row],[team]],fifa_ranking_2022_10_06[[#All],[team]],fifa_ranking_2022_10_06[[#All],[rank]])} -> 22 | F8: =fifa_ranking_2026_06_08[[#This Row],[2022_rank]]-fifa_ranking_2026_06_08[[#This Row],[2026_rank]] -> 15 | G8: 8 | H8: 1755.1002 | I8: 1755.8684 | J8: 87
A9: Netherlands | B9: NED | C9: UEFA | D9: 8 | E9: {=_xlfn.XLOOKUP(fifa_ranking_2026_06_08[[#This Row],[team]],fifa_ranking_2022_10_06[[#All],[team]],fifa_ranking_2022_10_06[[#All],[rank]])} -> 8 | F9: =fifa_ranking_2026_06_08[[#This Row],[2022_rank]]-fifa_ranking_2026_06_08[[#This Row],[2026_rank]] -> 0 | G9: 7 | H9: 1751.0978 | I9: 1757.8744 | J9: 56
A10: Belgium | B10: BEL | C10: UEFA | D10: 9 | E10: {=_xlfn.XLOOKUP(fifa_ranking_2026_06_08[[#This Row],[team]],fifa_ranking_2022_10_06[[#All],[team]],fifa_ranking_2022_10_06[[#All],[rank]])} -> 2 | F10: =fifa_ranking_2026_06_08[[#This Row],[2022_rank]]-fifa_ranking_2026_06_08[[#This Row],[2026_rank]] -> -7 | G10: 9 | H10: 1742.2359 | I10: 1734.7148 | J10: 54
A11: Germany | B11: GER | C11: UEFA | D11: 10 | E11: {=_xlfn.XLOOKUP(fifa_ranking_2026_06_08[[#This Row],[team]],fifa_ranking_2022_10_06[[#All],[team]],fifa_ranking_2022_10_06[[#All],[rank]])} -> 11 | F11: =fifa_ranking_2026_06_08[[#This Row],[2022_rank]]-fifa_ranking_2026_06_08[[#This Row],[2026_rank]] -> 1 | G11: 10 | H11: 1735.772 | I11: 1730.3714 | J11: 55
A12: Croatia | B12: CRO | C12: UEFA | D12: 11 | E12: {=_xlfn.XLOOKUP(fifa_ranking_2026_06_08[[#This Row],[team]],fifa_ranking_2022_10_06[[#All],[team]],fifa_ranking_2022_10_06[[#All],[rank]])} -> 12 | F12: =fifa_ranking_2026_06_08[[#This Row],[2022_rank]]-fifa_ranking_2026_06_08[[#This Row],[2026_rank]] -> 1 | G12: 11 | H12: 1714.8656 | I12: 1717.0664 | J12: 57
A13: Italy | B13: ITA | C13: UEFA | D13: 12 | E13: {=_xlfn.XLOOKUP(fifa_ranking_2026_06_08[[#This Row],[team]],fifa_ranking_2022_10_06[[#All],[team]],fifa_ranking_2022_10_06[[#All],[rank]])} -> 6 | F13: =fifa_ranking_2026_06_08[[#This Row],[2022_rank]]-fifa_ranking_2026_06_08[[#This Row],[2026_rank]] -> -6 | G13: 12 | H13: 1704.7338 | I13: 1700.3708 | J13: 53
... A212: San Marino | B212: SMR | C212: UEFA | D212: 211 | E212: {=_xlfn.XLOOKUP(fifa_ranking_2026_06_08[[#This Row],[team]],fifa_ranking_2022_10_06[[#All],[team]],fifa_ranking_2022_10_06[[#All],[rank]])} -> 211 | F212: =fifa_ranking_2026_06_08[[#This Row],[2022_rank]]-fifa_ranking_2026_06_08[[#This Row],[2026_rank]] -> 0 | G212: 211 | H212: 722.93373 | I212: 726.3306 | J212: 46

Sheet fifa_ranking_2022-10-06
A1: team | B1: team_code | C1: association | D1: rank | E1: previous_rank | F1: points | G1: previous_points
A2: Brazil | B2: BRA | C2: CONMEBOL | D2: 1 | E2: 1 | F2: 1841.3 | G2: 1837.56
A3: Belgium | B3: BEL | C3: UEFA | D3: 2 | E3: 2 | F3: 1816.71 | G3: 1821.92
A4: Argentina | B4: ARG | C4: CONMEBOL | D4: 3 | E4: 3 | F4: 1773.88 | G4: 1770.65
A5: France | B5: FRA | C5: UEFA | D5: 4 | E5: 4 | F5: 1759.78 | G5: 1764.85
A6: England | B6: ENG | C6: UEFA | D6: 5 | E6: 5 | F6: 1728.47 | G6: 1737.46
A7: Italy | B7: ITA | C7: UEFA | D7: 6 | E7: 7 | F7: 1726.14 | G7: 1713.86
A8: Spain | B8: ESP | C8: UEFA | D8: 7 | E8: 6 | F8: 1715.22 | G8: 1716.93
A9: Netherlands | B9: NED | C9: UEFA | D9: 8 | E9: 8 | F9: 1694.51 | G9: 1679.41
A10: Portugal | B10: POR | C10: UEFA | D10: 9 | E10: 9 | F10: 1676.56 | G10: 1678.65
A11: Denmark | B11: DEN | C11: UEFA | D11: 10 | E11: 10 | F11: 1666.57 | G11: 1665.47
A12: Germany | B12: GER | C12: UEFA | D12: 11 | E12: 11 | F12: 1650.21 | G12: 1658.96
A13: Croatia | B13: CRO | C13: UEFA | D13: 12 | E13: 15 | F13: 1645.64 | G13: 1632.15
... A212: San Marino | B212: SMR | C212: UEFA | D212: 211 | E212: 211 | F212: 762.22 | G212: 763.82

Sheet summary
C3: 2026 | D3: 2022
B4: Average Points | C4: =AVERAGE(fifa_ranking_2026_06_08[points]) -> 1229.9802 | D4: =AVERAGE(fifa_ranking_2022_10_06[points]) -> 1220.6873
B5: Min Points | C5: =MIN(fifa_ranking_2026_06_08[points]) -> 722.93373 | D5: =MIN(fifa_ranking_2022_10_06[points]) -> 762.22
B6: Max Point | C6: =MAX(fifa_ranking_2026_06_08[points]) -> 1876.1183 | D6: =MAX(fifa_ranking_2022_10_06[points]) -> 1841.3
B7: Median | C7: =MEDIAN(fifa_ranking_2026_06_08[points]) -> 1191.6554 | D7: =MEDIAN(fifa_ranking_2022_10_06[points]) -> 1192.09

Sheet pivot
A3: Row Labels | B3: Average of home_score | C3: Average of away_score | D3: Sum of Total Goals | G3: Row Labels | H3: Average of home_score | I3: Average of away_score | J3: Sum of Total Goals
A4: Final | B4: 2.3333333 | C4: 1.4761905 | D4: 80 | G4: Final | H4: 2.3333333 | I4: 1.4761905 | J4: 80
A5: Final stage | B5: 3.8333333 | C5: 1.3333333 | D5: 31 | G5: Final stage | H5: 3.8333333 | I5: 1.3333333 | J5: 31
A6: First group stage | B6: 1.9722222 | C6: 0.80555556 | D6: 100 | G6: First group stage | H6: 1.9722222 | I6: 0.80555556 | J6: 100
A7: First round | B7: 1.6458333 | C7: 0.91666667 | D7: 123 | G7: First round | H7: 1.6458333 | I7: 0.91666667 | J7: 123
A8: Group stage | B8: 1.6422487 | C8: 1.0221465 | D8: 1564 | G8: Group stage | H8: 1.6422487 | I8: 1.0221465 | J8: 1564
A9: Group stage play-off | B9: 3.2 | C9: 1 | D9: 21 | G9: Group stage play-off | H9: 3.2 | I9: 1 | J9: 21
A10: Quarter-finals | B10: 1.7285714 | C10: 1.0714286 | D10: 196 | G10: Quarter-finals | H10: 1.7285714 | I10: 1.0714286 | J10: 196
A11: Round of 16 | B11: 2.0412371 | C11: 1.0824742 | D11: 303 | G11: Round of 16 | H11: 2.0412371 | I11: 1.0824742 | J11: 303
A12: Second group stage | B12: 1.4166667 | C12: 1 | D12: 29 | G12: Second group stage | H12: 1.4166667 | I12: 1 | J12: 29
A13: Second round | B13: 1.875 | C13: 0.83333333 | D13: 65 | G13: Second round | H13: 1.875 | I13: 0.83333333 | J13: 65
A14: Semi-finals | B14: 2.1842105 | C14: 1.2894737 | D14: 132 | G14: Semi-finals | H14: 2.1842105 | I14: 1.2894737 | J14: 132
A15: Third-place match | B15: 2.35 | C15: 1.45 | D15: 76 | G15: Third-place match | H15: 2.35 | I15: 1.45 | J15: 76
A16: Grand Total | B16: 1.776971 | C16: 1.0446058 | D16: 2720 | G16: Grand Total | H16: 1.776971 | I16: 1.0446058 | J16: 2720
A23: Row Labels | B23: Sum of Total Goals
A24: 1930-1939 | B24: 224
A25: 1950-1959 | B25: 354
A26: 1960-1969 | B26: 178
A27: 1970-1979 | B27: 294
A28: 1980-1989 | B28: 278
A29: 1990-1999 | B29: 427
A30: 2000-2009 | B30: 308
A31: 2010-2019 | B31: 485
A32: 2020-2029 | B32: 172
A33: Grand Total | B33: 2720
A39: Row Labels | B39: Sum of Total Goals
A40: Final | B40: 80
A41: Final stage | B41: 31
A42: First group stage | B42: 100
A43: First round | B43: 123
A44: Group stage | B44: 1564
A45: Group stage play-off | B45: 21
A46: Quarter-finals | B46: 196
A47: Round of 16 | B47: 303
A48: Second group stage | B48: 29
A49: Second round | B49: 65
A50: Semi-finals | B50: 132
A51: Third-place match | B51: 76
A52: Grand Total | B52: 2720
A85: Row Labels | B85: Sum of Propularity | M85: Row Labels | N85: Average of AttendanceAvg
...

Sheet Dashboard
A1: World Cup Dashboard
A4: Average Points | C4: Max Points | E4: Min Points | G4: Avg.Home Score | H4: Avg.Away Score | I4: Total_Goals
A5: 2022 | B5: 2026 | C5: 2022 | D5: 2026 | E5: 2022 | F5: 2026 | H5: 2026 | I5: 2026
A6: =summary!D4 -> 1220.6873 | B6: =summary!C4 -> 1229.9802 | C6: =summary!D6 -> 1841.3 | D6: =summary!C6 -> 1876.1183 | E6: =summary!D5 -> 762.22 | F6: =summary!C5 -> 722.93373 | G6: =GETPIVOTDATA("Average of home_score",pivot!$A$3) -> 1.776971 | H6: =GETPIVOTDATA("Average of away_score",pivot!$A$3) -> 1.0446058 | I6: =GETPIVOTDATA("Sum of Total Goals",pivot!$A$3) -> 2720
I21: Comparasion of Ranking
I23: Teams | J23: Top Rank 2026 | K23: Top Rank 2022
I24: Argentina | J24: 1 | K24: 3
I25: Spain | J25: 2 | K25: 7
I26: France | J26: 3 | K26: 4
I27: England | J27: 4 | K27: 5
I28: Portugal | J28: 5 | K28: 9
I29: Brazil | J29: 6 | K29: 1
I30: Morocco | J30: 7 | K30: 22
I31: Grand Total | J31: 7 | K31: 22

Sheet matches_1930_2022
A1: home_team | B1: away_team | C1: home_score | D1: home_xg | E1: home_penalty | F1: away_score | G1: away_xg | H1: away_penalty | I1: home_manager | J1: home_captain | K1: away_manager | L1: away_captain | M1: Attendance | N1: Venue | O1: Officials | P1: Round | Q1: Date | R1: Score | S1: Referee | T1: Notes | U1: Host | V1: Year | W1: home_goal | X1: away_goal | Y1: home_goal_long | Z1: away_goal_long | AA1: home_own_goal | AB1: away_own_goal | AC1: home_penalty_goal | AD1: away_penalty_goal | AE1: home_penalty_miss_long | AF1: away_penalty_miss_long | AG1: home_penalty_shootout_goal_long | AH1: away_penalty_shootout_goal_long | AI1: home_penalty_shootout_miss_long | AJ1: away_penalty_shootout_miss_long | AK1: home_red_card | AL1: away_red_card | AM1: home_yellow_red_card | AN1: away_yellow_red_card | AO1: home_yellow_card_long | AP1: away_yellow_card_long | AQ1: home_substitute_in_long | AR1: away_substitute_in_long
A2: Argentina | B2: France | C2: 3 | D2: 3.3 | E2: 4 | F2: 3 | G2: 2.2 | H2: 2 | I2: Lionel Scaloni | J2: Lionel Messi | K2: Didier Deschamps | L2: Hugo Lloris | M2: 88966 | N2: Lusail Iconic Stadium, Lusail | O2: Szymon Marciniak (Referee) · Paweł Sokolnicki (AR1) · Tomasz Listkiewicz (AR2) · Ismail Elfath (4th) · Tomasz Kwiatkowski (VAR) | P2: Final | Q2: 44913 | R2: (4) 3–3 (2) | S2: Szymon Marciniak | T2: Argentina won on penalty kicks following extra time | U2: Qatar | V2: 2022 | W2: Ángel Di María · 36|Lionel Messi · 108 | X2: Kylian Mbappé · 81 | Y2: ['36&rsquor;|2:0|Ángel Di María|Assist:|Alexis Mac Allister', '108&rsquor;|3:2|Lionel Messi'] | Z2: ['81&rsquor;|2:2|Kylian Mbappé|Assist:|Marcus Thuram'] | AC2: Lionel Messi (P) · 23 | AD2: Kylian Mbappé (P) · 80|Kylian Mbappé (P) · 118 | AG2: ['2|1:1|Lionel Messi', '4|2:1|Paulo Dybala', '6|3:1|Leandro Paredes', '8|4:2|Gonzalo Montiel'] | AH2: ['1|0:1|Kylian Mbappé', '7|3:2|Randal Kolo Muani'] | AJ2: ['3|1:1|Kingsley Coman', '5|2:1|Aurélien Tchouaméni'] | AO2: ['45+7&rsquor;|2:0|Enzo Fernández', '90+8&rsquor;|2:2|Marcos Acuña', '114&rsquor;|3:2|Leandro Paredes', '116&rsquor;|3:2|Gonzalo Montiel', '120+4&rsquor;|3:3|Emiliano Martínez'] | AP2: ['55&rsquor;|2:0|Adrien Rabiot', '87&rsquor;|2:2|Marcus Thuram', '90+5&rsquor;|2:2|Olivier Giroud'] | AQ2: ['64&rsquor;|2:0|Marcos Acuña|for Ángel Di María', '91&rsquor;|2:2|Gonzalo Montiel|for Nahuel Molina', '102&rsquor;|2:2|Leandro Paredes|for Rodrigo De Paul', '103&rsquor;|2:2|Lautaro Martínez|for Julián Álvarez', '116&rsquor;|3:2|Germán Pezzella|for Alexis Mac Allister', '120+1&rsquor;|3:3|Paulo Dybala|for Nicolás Tagliafico'] | AR2: ['41&rsquor;|2:0|Randal Kolo Muani|for Ousmane Dembélé', '41&rsquor;|2:0|Marcus Thuram|for Olivier Giroud', '71&rsquor;|2:0|Eduardo Camavinga|for Theo Hernández', '71&rsquor;|2:0|Kingsley Coman|for Antoine Griezmann', '96&rsquor;|2:2|Youssouf Fofana|for Adrien Rabiot', '113&rsquor;|3:2|Ibrahima Konaté|for Raphaël Varane', '120+1&rsquor;|3:3|Axel Disasi|for Jules Koundé']
A3: Croatia | B3: Morocco | C3: 2 | D3: 0.7 | F3: 1 | G3: 1.2 | I3: Zlatko Dalić | J3: Luka Modrić | K3: Hoalid Regragui | L3: Hakim Ziyech | M3: 44137 | N3: Khalifa International Stadium, Doha | O3: Abdulrahman Ibrahim Al Jassim (Referee) · Taleb Salem Al Marri (AR1) · Saoud Ahmed Al Maqaleh (AR2) · Raphael Claus (4th) · Julio Bascuñán (VAR) | P3: Third-place match | Q3: 44912 | R3: 2–1 | S3: Abdulrahman Ibrahim Al Jassim | U3: Qatar | V3: 2022 | W3: Joško Gvardiol · 7|Mislav Oršić · 42 | X3: Achraf Dari · 9 | Y3: ['7&rsquor;|1:0|Joško Gvardiol|Assist:|Ivan Perišić', '42&rsquor;|2:1|Mislav Oršić|Assist:|Marko Livaja'] | Z3: ['9&rsquor;|1:1|Achraf Dari'] | AP3: ['69&rsquor;|2:1|Azzedine Ounahi', '84&rsquor;|2:1|Selim Amallah'] | AQ3: ['61&rsquor;|2:1|Nikola Vlašić|for Andrej Kramarić', '66&rsquor;|2:1|Bruno Petković|for Marko Livaja', '66&rsquor;|2:1|Mario Pašalić|for Lovro Majer', '90+5&rsquor;|2:1|Kristijan Jakić|for Mislav Oršić'] | AR3: ['46&rsquor;|2:1|Ilias Chair|for Abdelhamid Sabiri', '56&rsquor;|2:1|Azzedine Ounahi|for Bilal El Khannous', '64&rsquor;|2:1|Anass Zaroury|for Sofiane Boufal', '64&rsquor;|2:1|Badr Banoun|for Achraf Dari', '66&rsquor;|2:1|Selim Amallah|for Jawad El Yamiq']
A4: France | B4: Morocco | C4: 2 | D4: 2 | F4: 0 | G4: 0.9 | I4: Didier Deschamps | J4: Hugo Lloris | K4: Hoalid Regragui | L4: Romain Saïss | M4: 68294 | N4: Al Bayt Stadium, Al Khor | O4: César Arturo Ramos (Referee) · Alberto Morín (AR1) · Miguel Ángel Hernández (AR2) · Jesús Valenzuela (4th) · Drew Fischer (VAR) | P4: Semi-finals | Q4: 44909 | R4: 2–0 | S4: César Arturo Ramos | U4: Qatar | V4: 2022 | W4: Theo Hernández · 5|Randal Kolo Muani · 79 | Y4: ['5&rsquor;|1:0|Theo Hernández', '79&rsquor;|2:0|Randal Kolo Muani'] | AP4: ['27&rsquor;|1:0|Sofiane Boufal'] | AQ4: ['65&rsquor;|1:0|Marcus Thuram|for Olivier Giroud', '79&rsquor;|1:0|Randal Kolo Muani|for Ousmane Dembélé'] | AR4: ['21&rsquor;|1:0|Selim Amallah|for Romain Saïss', '46&rsquor;|1:0|Yahya Attiat Allah|for Noussair Mazraoui', '66&rsquor;|1:0|Abderrazak Hamdallah|for Youssef En-Nesyri', '66&rsquor;|1:0|Zakaria Aboukhlal|for Sofiane Boufal', '78&rsquor;|1:0|Abdessamad Ezzalzouli|for Selim Amallah']
A5: Argentina | B5: Croatia | C5: 3 | D5: 2.3 | F5: 0 | G5: 0.5 | I5: Lionel Scaloni | J5: Lionel Messi | K5: Zlatko Dalić | L5: Luka Modrić | M5: 88966 | N5: Lusail Iconic Stadium, Lusail | O5: Daniele Orsato (Referee) · Ciro Carbone (AR1) · Alessandro Giallatini (AR2) · Mohammed Abdulla Hassan (4th) · Massimiliano Irrati (VAR) | P5: Semi-finals | Q5: 44908 | R5: 3–0 | S5: Daniele Orsato | U5: Qatar | V5: 2022 | W5: Julián Álvarez · 39|Julián Álvarez · 69 | Y5: ['39&rsquor;|2:0|Julián Álvarez', '69&rsquor;|3:0|Julián Álvarez|Assist:|Lionel Messi'] | AC5: Lionel Messi (P) · 34 | AO5: ['68&rsquor;|2:0|Cristian Romero', '71&rsquor;|3:0|Nicolás Otamendi'] | AP5: ['32&rsquor;|0:0|Mateo Kovačić', '32&rsquor;|0:0|Dominik Livaković'] | AQ5: ['62&rsquor;|2:0|Lisandro Martínez|for Leandro Paredes', '74&rsquor;|3:0|Exequiel Palacios|for Rodrigo De Paul', '74&rsquor;|3:0|Paulo Dybala|for Julián Álvarez', '86&rsquor;|3:0|Ángel Correa|for Alexis Mac Allister', '86&rsquor;|3:0|Juan Foyth|for Nahuel Molina'] | AR5: ['46&rsquor;|2:0|Mislav Oršić|for Borna Sosa', '46&rsquor;|2:0|Nikola Vlašić|for Mario Pašalić', '50&rsquor;|2:0|Bruno Petković|for Marcelo Brozović', '72&rsquor;|3:0|Marko Livaja|for Andrej Kramarić', '81&rsquor;|3:0|Lovro Majer|for Luka Modrić']
A6: Morocco | B6: Portugal | C6: 1 | D6: 1.4 | F6: 0 | G6: 0.9 | I6: Hoalid Regragui | J6: Romain Saïss | K6: Fernando Santos | L6: Pepe | M6: 44198 | N6: Al Thumama Stadium, ath-Thumāma | O6: Facundo Tello (Referee) · Ezequiel Brailovsky (AR1) · Gabriel Chade (AR2) · Iván Barton (4th) · Mauro Vigliano (VAR) | P6: Quarter-finals | Q6: 44905 | R6: 1–0 | S6: Facundo Tello | U6: Qatar | V6: 2022 | W6: Youssef En-Nesyri · 42 | Y6: ['42&rsquor;|1:0|Youssef En-Nesyri|Assist:|Yahya Attiat Allah'] | AM6: Walid Cheddira · 90+3 | AO6: ['70&rsquor;|1:0|Achraf Dari', '90+1&rsquor;|1:0|Walid Cheddira'] | AP6: ['87&rsquor;|1:0|Vitinha'] | AQ6: ['57&rsquor;|1:0|Achraf Dari|for Romain Saïss', '65&rsquor;|1:0|Walid Cheddira|for Selim Amallah', '65&rsquor;|1:0|Badr Banoun|for Youssef En-Nesyri', '81&rsquor;|1:0|Zakaria Aboukhlal|for Hakim Ziyech', '82&rsquor;|1:0|Yahya Jabrane|for Sofiane Boufal'] | AR6: ['51&rsquor;|1:0|João Cancelo|for Raphaël Guerreiro', '51&rsquor;|1:0|Cristiano Ronaldo|for Rúben Neves', '69&rsquor;|1:0|Vitinha|for Otávio', '69&rsquor;|1:0|Rafael Leão|for Gonçalo Ramos', '79&rsquor;|1:0|Ricardo Horta|for Diogo Dalot']
A7: England | B7: France | C7: 1 | D7: 2.4 | F7: 2 | G7: 0.9 | I7: Gareth Southgate | J7: Harry Kane | K7: Didier Deschamps | L7: Hugo Lloris | M7: 68895 | N7: Al Bayt Stadium, Al Khor | O7: Wilton Sampaio (Referee) · Bruno Boschilia (AR1) · Bruno Pires (AR2) · Mohammed Abdulla Hassan (4th) · Nicolás Gallo (VAR) | P7: Quarter-finals | Q7: 44905 | R7: 1–2 | S7: Wilton Sampaio | U7: Qatar | V7: 2022 | X7: Aurélien Tchouaméni · 17|Olivier Giroud · 78 | Z7: ['17&rsquor;|0:1|Aurélien Tchouaméni|Assist:|Antoine Griezmann', '78&rsquor;|1:2|Olivier Giroud|Assist:|Antoine Griezmann'] | AC7: Harry Kane (P) · 54 | AE7: ['84&rsquor;|1:2|Harry Kane|Penalty Miss'] | AO7: ['90&rsquor;|1:2|Harry Maguire'] | AP7: ['43&rsquor;|0:1|Antoine Griezmann', '47&rsquor;|0:1|Ousmane Dembélé', '82&rsquor;|1:2|Theo Hernández'] | AQ7: ['79&rsquor;|1:2|Raheem Sterling|for Bukayo Saka', '79&rsquor;|1:2|Mason Mount|for Jordan Henderson', '85&rsquor;|1:2|Marcus Rashford|for Phil Foden', '90+8&rsquor;|1:2|Jack Grealish|for John Stones'] | AR7: ['79&rsquor;|1:2|Kingsley Coman|for Ousmane Dembélé']
A8: Croatia | B8: Brazil | C8: 1 | D8: 0.6 | E8: 4 | F8: 1 | G8: 2.5 | H8: 2 | I8: Zlatko Dalić | J8: Luka Modrić | K8: Tite | L8: Thiago Silva | M8: 43893 | N8: Education City Stadium, Doha | O8: Michael Oliver (Referee) · Stuart Burt (AR1) · Gary Beswick (AR2) · Mustapha Ghorbal (4th) · Pol van Boekel (VAR) | P8: Quarter-finals | Q8: 44904 | R8: (4) 1–1 (2) | S8: Michael Oliver | T8: Croatia won on penalty kicks following extra time | U8: Qatar | V8: 2022 | W8: Bruno Petković · 117 | X8: Neymar · 105+1 | Y8: ['117&rsquor;|1:1|Bruno Petković|Assist:|Mislav Oršić'] | Z8: ['105+1&rsquor;|0:1|Neymar|Assist:|Lucas Paquetá'] | AG8: ['1|1:0|Nikola Vlašić', '3|2:0|Lovro Majer', '5|3:1|Luka Modrić', '7|4:2|Mislav Oršić'] | AH8: ['4|2:1|Casemiro', '6|3:2|Pedro'] | AJ8: ['2|1:0|Rodrygo', '8|4:2|Marquinhos'] | AO8: ['31&rsquor;|0:0|Marcelo Brozović', '117&rsquor;|1:1|Bruno Petković'] | AP8: ['25&rsquor;|0:0|Danilo', '68&rsquor;|0:0|Casemiro', '77&rsquor;|0:0|Marquinhos'] | AQ8: ['72&rsquor;|0:0|Nikola Vlašić|for Mario Pašalić', '72&rsquor;|0:0|Bruno Petković|for Andrej Kramarić', '106&rsquor;|0:1|Lovro Majer|for Mateo Kovačić', '110&rsquor;|0:1|Ante Budimir|for Borna Sosa', '114&rsquor;|0:1|Mislav Oršić|for Marcelo Brozović'] | AR8: ['56&rsquor;|0:0|Antony|for Raphinha', '64&rsquor;|0:0|Rodrygo|for Vinicius Júnior', '84&rsquor;|0:0|Pedro|for Richarlison', '106&rsquor;|0:1|Alex Sandro|for Éder Militão', '106&rsquor;|0:1|Fred|for Lucas Paquetá']
A9: Netherlands | B9: Argentina | C9: 2 | D9: 0.6 | E9: 3 | F9: 2 | G9: 1.9 | H9: 4 | I9: Louis van Gaal | J9: Virgil van Dijk | K9: Lionel Scaloni | L9: Lionel Messi | M9: 88235 | N9: Lusail Iconic Stadium, Lusail | O9: Antonio Matéu (Referee) · Pau Cebrián (AR1) · Roberto Díaz (AR2) · Victor Gomes (4th) · Alejandro Hernández (VAR) | P9: Quarter-finals | Q9: 44904 | R9: (3) 2–2 (4) | S9: Antonio Matéu | T9: Argentina won on penalty kicks following extra time | U9: Qatar | V9: 2022 | W9: Wout Weghorst · 83|Wout Weghorst · 90+11 | X9: Nahuel Molina · 35 | Y9: ['83&rsquor;|1:2|Wout Weghorst|Assist:|Steven Berghuis', '90+11&rsquor;|2:2|Wout Weghorst|Assist:|Teun Koopmeiners'] | Z9: ['35&rsquor;|0:1|Nahuel Molina|Assist:|Lionel Messi'] | AD9: Lionel Messi (P) · 73 | AG9: ['5|1:2|Teun Koopmeiners', '7|2:3|Wout Weghorst', '9|3:3|Luuk de Jong'] | AH9: ['2|0:1|Lionel Messi', '4|0:2|Leandro Paredes', '6|1:3|Gonzalo Montiel', '10|3:4|Lautaro Martínez'] | AI9: ['1|0:0|Virgil van Dijk', '3|0:1|Steven Berghuis'] | AJ9: ['8|2:3|Enzo Fernández'] | AM9: Denzel Dumfries · 120+3 | AO9: ['43&rsquor;|0:1|Jurriën Timber', '45+2&rsquor;|0:1|Wout Weghorst', '75&rsquor;|0:2|Memphis', '88&rsquor;|1:2|Steven Berghuis', '90+12&rsquor;|2:2|Steven Bergwijn', '120+2&rsquor;|2:2|Noa Lang', '120+2&rsquor;|2:2|Denzel Dumfries'] | AP9: ['31&rsquor;|0:0|Walter Samuel', '43&rsquor;|0:1|Marcos Acuña', '45&rsquor;|0:1|Cristian Romero', '75&rsquor;|0:2|Lisandro Martínez', '89&rsquor;|1:2|Leandro Paredes', '90&rsquor;|1:2|Lionel Scaloni', '90+10&rsquor;|1:2|Lionel Messi', '90+12&rsquor;|2:2|Nicolás Otamendi', '109&rsquor;|2:2|Gonzalo Montiel', '112&rsquor;|2:2|Germán Pezzella'] | AQ9: ['46&rsquor;|0:1|Steven Berghuis|for Steven Bergwijn', '46&rsquor;|0:1|Teun Koopmeiners|for Marten de Roon', '64&rsquor;|0:1|Luuk de Jong|for Daley Blind', '78&rsquor;|0:2|Wout Weghorst|for Memphis', '113&rsquor;|2:2|Noa Lang|for Cody Gakpo'] | AR9: ['66&rsquor;|0:1|Leandro Paredes|for Rodrigo De Paul', '78&rsquor;|0:2|Nicolás Tagliafico|for Marcos Acuña', '78&rsquor;|0:2|Germán Pezzella|for Cristian Romero', '82&rsquor;|0:2|Lautaro Martínez|for Julián Álvarez', '106&rsquor;|2:2|Gonzalo Montiel|for Nahuel Molina', '112&rsquor;|2:2|Ángel Di María|for Lisandro Martínez']
A10: Morocco | B10: Spain | C10: 0 | D10: 0.7 | E10: 3 | F10: 0 | G10: 1 | H10: 0 | I10: Hoalid Regragui | J10: Romain Saïss | K10: Luis Enrique | L10: Sergio Busquets | M10: 44667 | N10: Education City Stadium, Doha | O10: Fernando Rapallini (Referee) · Juan Pablo Belatti (AR1) · Diego Bonfá (AR2) · Raphael Claus (4th) · Mauro Vigliano (VAR) | P10: Round of 16 | Q10: 44901 | R10: (3) 0–0 (0) | S10: Fernando Rapallini | T10: Morocco won on penalty kicks following extra time | U10: Qatar | V10: 2022 | AG10: ['1|1:0|Abdelhamid Sabiri', '3|2:0|Hakim Ziyech', '7|3:0|Achraf Hakimi'] | AI10: ['5|2:0|Badr Banoun'] | AJ10: ['2|1:0|Pablo Sarabia', '4|2:0|Carlos Soler', '6|2:0|Sergio Busquets'] | AO10: ['90&rsquor;|0:0|Romain Saïss'] | AP10: ['77&rsquor;|0:0|Aymeric Laporte'] | AQ10: ['66&rsquor;|0:0|Abdessamad Ezzalzouli|for Sofiane Boufal', '82&rsquor;|0:0|Walid Cheddira|for Selim Amallah', '82&rsquor;|0:0|Abdelhamid Sabiri|for Youssef En-Nesyri', '82&rsquor;|0:0|Yahya Attiat Allah|for Noussair Mazraoui', '84&rsquor;|0:0|Jawad El Yamiq|for Nayef Aguerd', '120&rsquor;|0:0|Badr Banoun|for Azzedine Ounahi'] | AR10: ['63&rsquor;|0:0|Álvaro Morata|for Marco Asensio', '63&rsquor;|0:0|Carlos Soler|for Gavi', '75&rsquor;|0:0|Nico Williams|for Ferrán Torres', '98&rsquor;|0:0|Ansu Fati|for Dani Olmo', '98&rsquor;|0:0|Alejandro Balde|for Jordi Alba', '118&rsquor;|0:0|Pablo Sarabia|for Nico Williams']
A11: Portugal | B11: Switzerland | C11: 6 | D11: 2.3 | F11: 1 | G11: 1.2 | I11: Fernando Santos | J11: Pepe | K11: Murat Yakin | L11: Granit Xhaka | M11: 83720 | N11: Lusail Iconic Stadium, Lusail | O11: César Arturo Ramos (Referee) · Alberto Morín (AR1) · Miguel Ángel Hernández (AR2) · István Kovács (4th) · Drew Fischer (VAR) | P11: Round of 16 | Q11: 44901 | R11: 6–1 | S11: César Arturo Ramos | U11: Qatar | V11: 2022 | W11: Gonçalo Ramos · 17|Pepe · 33|Gonçalo Ramos · 51|Raphaël Guerreiro · 55|Gonçalo Ramos · 67|Rafael Leão · 90+2 | X11: Manuel Akanji · 58 | Y11: ['17&rsquor;|1:0|Gonçalo Ramos|Assist:|João Félix', '33&rsquor;|2:0|Pepe|Assist:|Bruno Fernandes', '51&rsquor;|3:0|Gonçalo Ramos|Assist:|Diogo Dalot', '55&rsquor;|4:0|Raphaël Guerreiro|Assist:|Gonçalo Ramos', '67&rsquor;|5:1|Gonçalo Ramos|Assist:|João Félix', '90+2&rsquor;|6:1|Rafael Leão|Assist:|Raphaël Guerreiro'] | Z11: ['58&rsquor;|4:1|Manuel Akanji'] | AP11: ['43&rsquor;|2:0|Fabian Schär', '59&rsquor;|4:1|Eray Cömert'] | AQ11: ['73&rsquor;|5:1|Cristiano Ronaldo|for Gonçalo Ramos', '74&rsquor;|5:1|Ricardo Horta|for João Félix', '74&rsquor;|5:1|Vitinha|for Otávio', '81&rsquor;|5:1|Rúben Neves|for Bernardo Silva', '87&rsquor;|5:1|Rafael Leão|for Bruno Fernandes'] | AR11: ['46&rsquor;|2:0|Eray Cömert|for Fabian Schär', '54&rsquor;|3:0|Denis Zakaria|for Remo Freuler', '54&rsquor;|3:0|Haris Seferović|for Djibril Sow', '66&rsquor;|4:1|Noah Okafor|for Ruben Vargas', '89&rsquor;|5:1|Ardon Jasari|for Breel Embolo']
A12: Japan | B12: Croatia | C12: 1 | D12: 1.2 | E12: 1 | F12: 1 | G12: 1.4 | H12: 3 | I12: Hajime Moriyasu | J12: Maya Yoshida | K12: Zlatko Dalić | L12: Luka Modrić | M12: 42523 | N12: Al Janoub Stadium, Al Wakrah | O12: Ismail Elfath (Referee) · Corey Parker (AR1) · Kyle Atkins (AR2) · Mustapha Ghorbal (4th) · Nicolás Gallo (VAR) | P12: Round of 16 | Q12: 44900 | R12: (1) 1–1 (3) | S12: Ismail Elfath | T12: Croatia won on penalty kicks following extra time | U12: Qatar | V12: 2022 | W12: Daizen Maeda · 43 | X12: Ivan Perišić · 55 | Y12: ['43&rsquor;|1:0|Daizen Maeda|Assist:|Maya Yoshida'] | Z12: ['55&rsquor;|1:1|Ivan Perišić|Assist:|Dejan Lovren'] | AG12: ['5|1:2|Takuma Asano'] | AH12: ['2|0:1|Nikola Vlašić', '4|0:2|Marcelo Brozović', '8|1:3|Mario Pašalić'] | AI12: ['1|0:0|Takumi Minamino', '3|0:1|Kaoru Mitoma', '7|1:2|Maya Yoshida'] | AJ12: ['6|1:2|Marko Livaja'] | AP12: ['90&rsquor;|1:1|Mateo Kovačić', '116&rsquor;|1:1|Borna Barišić'] | AQ12: ['64&rsquor;|1:1|Takuma Asano|for Daizen Maeda', '64&rsquor;|1:1|Kaoru Mitoma|for Yuto Nagatomo', '75&rsquor;|1:1|Hiroki Sakai|for Daichi Kamada', '87&rsquor;|1:1|Takumi Minamino|for Ritsu Doan', '106&rsquor;|1:1|Ao Tanaka|for Hidemasa Morita'] | AR12: ['62&rsquor;|1:1|Ante Budimir|for Bruno Petković', '68&rsquor;|1:1|Mario Pašalić|for Andrej Kramarić', '99&rsquor;|1:1|Nikola Vlašić|for Mateo Kovačić', '99&rsquor;|1:1|Lovro Majer|for Luka Modrić', '106&rsquor;|1:1|Marko Livaja|for Ante Budimir', '106&rsquor;|1:1|Mislav Oršić|for Ivan Perišić']
A13: Brazil | B13: Korea Republic | C13: 4 | D13: 3.6 | F13: 1 | G13: 0.5 | I13: Tite | J13: Thiago Silva | K13: Paulo Bento | L13: Son Heung-min | M13: 43847 | N13: Stadium 974, Doha | O13: Clément Turpin (Referee) · Nicolas Danos (AR1) · Cyril Gringore (AR2) · Slavko Vinčič (4th) · Jérôme Brisard (VAR) | P13: Round of 16 | Q13: 44900 | R13: 4–1 | S13: Clément Turpin | U13: Qatar | V13: 2022 | W13: Vinicius Júnior · 7|Richarlison · 29|Lucas Paquetá · 36 | X13: Paik Seung-ho · 76 | Y13: ['7&rsquor;|1:0|Vinicius Júnior|Assist:|Raphinha', '29&rsquor;|3:0|Richarlison|Assist:|Thiago Silva', '36&rsquor;|4:0|Lucas Paquetá|Assist:|Vinicius Júnior'] | Z13: ['76&rsquor;|4:1|Paik Seung-ho'] | AC13: Neymar (P) · 11 | AP13: ['44&rsquor;|4:0|Jung Woo-young'] | AQ13: ['63&rsquor;|4:0|Dani Alves|for Éder Militão', '72&rsquor;|4:0|Gleison Bremer|for Danilo', '72&rsquor;|4:0|Martinelli|for Vinicius Júnior', '80&rsquor;|4:1|Wéverton|for Alisson', '81&rsquor;|4:1|Rodrygo|for Neymar'] | AR13: ['46&rsquor;|4:0|Hong Chul|for Kim Jin-su', '46&rsquor;|4:0|Son Jun-ho|for Jung Woo-young', '65&rsquor;|4:0|Paik Seung-ho|for Hwang In-beom', '74&rsquor;|4:0|Lee Kangin|for Lee Jae-sung', '80&rsquor;|4:1|Hwang Ui-jo|for Cho Guesung']
A14: France | B14: Poland | C14: 3 | D14: 1.4 | F14: 1 | G14: 1.7 | I14: Didier Deschamps | J14: Hugo Lloris | K14: Czesław Michniewicz | L14: Robert Lewandowski | M14: 40989 | N14: Al Thumama Stadium, ath-Thumāma | O14: Jesús Valenzuela (Referee) · Jorge Urrego (AR1) · Tulio Moreno (AR2) · Kevin Ortega (4th) · Juan Soto (VAR) | P14: Round of 16 | Q14: 44899 | R14: 3–1 | S14: Jesús Valenzuela | U14: Qatar | V14: 2022 | W14: Olivier Giroud · 44|Kylian Mbappé · 74|Kylian Mbappé · 90+1 | Y14: ['44&rsquor;|1:0|Olivier Giroud|Assist:|Kylian Mbappé', '74&rsquor;|2:0|Kylian Mbappé|Assist:|Ousmane Dembélé', '90+1&rsquor;|3:0|Kylian Mbappé|Assist:|Marcus Thuram'] | AD14: Robert Lewandowski (P) · 90+9 | AO14: ['32&rsquor;|0:0|Aurélien Tchouaméni'] | AP14: ['47&rsquor;|1:0|Bartosz Bereszyński', '88&rsquor;|2:0|Matty Cash'] | AQ14: ['66&rsquor;|1:0|Youssouf Fofana|for Aurélien Tchouaméni', '76&rsquor;|2:0|Kingsley Coman|for Ousmane Dembélé', '76&rsquor;|2:0|Marcus Thuram|for Olivier Giroud', '90+2&rsquor;|3:0|Axel Disasi|for Jules Koundé'] | AR14: ['64&rsquor;|1:0|Arkadiusz Milik|for Sebastian Szymański', '71&rsquor;|1:0|Nicola Zalewski|for Jakub Kamiński', '71&rsquor;|1:0|Krystian Bielik|for Grzegorz Krychowiak', '86&rsquor;|2:0|Jan Bednarek|for Jakub Kiwior', '87&rsquor;|2:0|Kamil Grosicki|for Przemysław Frankowski']
A15: England | B15: Senegal | C15: 3 | D15: 1 | F15: 0 | G15: 0.8 | I15: Gareth Southgate | J15: Harry Kane | K15: Aliou Cissé | L15: Kalidou Koulibaly | M15: 65985 | N15: Al Bayt Stadium, Al Khor | O15: Iván Barton (Referee) · David Morán (AR1) · Kathryn Nesbitt (AR2) · Said Martínez (4th) · Drew Fischer (VAR) | P15: Round of 16 | Q15: 44899 | R15: 3–0 | S15: Iván Barton | U15: Qatar | V15: 2022 | W15: Jordan Henderson · 39|Harry Kane · 45+3|Bukayo Saka · 57 | Y15: ['39&rsquor;|1:0|Jordan Henderson|Assist:|Jude Bellingham', '45+3&rsquor;|2:0|Harry Kane|Assist:|Phil Foden', '57&rsquor;|3:0|Bukayo Saka|Assist:|Phil Foden'] | AP15: ['76&rsquor;|3:0|Kalidou Koulibaly'] | AQ15: ['65&rsquor;|3:0|Jack Grealish|for Phil Foden', '65&rsquor;|3:0|Marcus Rashford|for Bukayo Saka', '76&rsquor;|3:0|Eric Dier|for John Stones', '77&rsquor;|3:0|Mason Mount|for Jude Bellingham', '82&rsquor;|3:0|Kalvin Phillips|for Jordan Henderson'] | AR15: ['46&rsquor;|2:0|Pape Matar Sarr|for Krépin Diatta', '46&rsquor;|2:0|Pape Gueye|for Pathé Ciss', '46&rsquor;|2:0|Bamba Dieng|for Iliman Ndiaye', '72&rsquor;|3:0|Famara Diedhiou|for Boulaye Dia', '84&rsquor;|3:0|Fodé Ballo-Touré|for Ismail Jakobs']
A16: Netherlands | B16: United States | C16: 3 | D16: 1.7 | F16: 1 | G16: 1.5 | I16: Louis van Gaal | J16: Virgil van Dijk | K16: Gregg Berhalter | L16: Tyler Adams | M16: 44846 | N16: Khalifa International Stadium, Doha | O16: Wilton Sampaio (Referee) · Bruno Boschilia (AR1) · Bruno Pires (AR2) · Andrés Matonte (4th) · Nicolás Gallo (VAR) | P16: Round of 16 | Q16: 44898 | R16: 3–1 | S16: Wilton Sampaio | U16: Qatar | V16: 2022 | W16: Memphis · 10|Daley Blind · 45+1|Denzel Dumfries · 81 | X16: Haji Wright · 76 | Y16: ['10&rsquor;|1:0|Memphis|Assist:|Denzel Dumfries', '45+1&rsquor;|2:0|Daley Blind|Assist:|Denzel Dumfries', '81&rsquor;|3:1|Denzel Dumfries|Assist:|Daley Blind'] | Z16: ['76&rsquor;|2:1|Haji Wright|Assist:|Christian Pulisic'] | AO16: ['60&rsquor;|2:0|Teun Koopmeiners', '87&rsquor;|3:1|Frenkie de Jong'] | AQ16: ['46&rsquor;|2:0|Teun Koopmeiners|for Davy Klaassen', '46&rsquor;|2:0|Steven Bergwijn|for Marten de Roon', '82&rsquor;|3:1|Xavi Simons|for Memphis', '90+3&rsquor;|3:1|Matthijs de Ligt|for Nathan Aké', '90+4&rsquor;|3:1|Wout Weghorst|for Cody Gakpo'] | AR16: ['46&rsquor;|2:0|Gio Reyna|for Jesús Ferreira', '67&rsquor;|2:0|Brenden Aaronson|for Timothy Weah', '67&rsquor;|2:0|Haji Wright|for Weston McKennie', '75&rsquor;|2:0|DeAndre Yedlin|for Sergiño Dest', '90+2&rsquor;|3:1|Jordan Morris|for Antonee Robinson']
A17: Argentina | B17: Australia | C17: 2 | D17: 1.6 | F17: 1 | G17: 0.6 | I17: Lionel Scaloni | J17: Lionel Messi | K17: Graham Arnold | L17: Mathew Ryan | M17: 45032 | N17: Ahmed bin Ali Stadium, Umm al-Afā'ī | O17: Szymon Marciniak (Referee) · Paweł Sokolnicki (AR1) · Tomasz Listkiewicz (AR2) · Mario Escobar (4th) · Tomasz Kwiatkowski (VAR) | P17: Round of 16 | Q17: 44898 | R17: 2–1 | S17: Szymon Marciniak | U17: Qatar | V17: 2022 | W17: Lionel Messi · 35|Julián Álvarez · 57 | Y17: ['35&rsquor;|1:0|Lionel Messi|Assist:|Nicolás Otamendi', '57&rsquor;|2:0|Julián Álvarez'] | AB17: Enzo Fernández (OG) · 77 | AP17: ['15&rsquor;|0:0|Jackson Irvine', '38&rsquor;|1:0|Miloš Degenek'] | AQ17: ['50&rsquor;|1:0|Lisandro Martínez|for Papu Gómez', '71&rsquor;|2:0|Lautaro Martínez|for Julián Álvarez', '72&rsquor;|2:0|Nicolás Tagliafico|for Marcos Acuña', '80&rsquor;|2:1|Exequiel Palacios|for Nahuel Molina', '80&rsquor;|2:1|Gonzalo Montiel|for Alexis Mac Allister'] | AR17: ['58&rsquor;|2:0|Craig Goodwin|for Riley McGree', '58&rsquor;|2:0|Ajdin Hrustic|for Keanu Baccus', '72&rsquor;|2:0|Jamie Maclaren|for Mitchell Duke', '72&rsquor;|2:0|Fran Karačić|for Miloš Degenek', '72&rsquor;|2:0|Garang Kuol|for Mathew Leckie']
A18: Korea Republic | B18: Portugal | C18: 2 | D18: 1.7 | F18: 1 | G18: 1.3 | I18: Sérgio Costa | J18: Son Heung-min | K18: Fernando Santos | L18: Cristiano Ronaldo | M18: 44097 | N18: Education City Stadium, Doha | O18: Facundo Tello (Referee) · Ezequiel Brailovsky (AR1) · Gabriel Chade (AR2) · Maguette Ndiaye (4th) · Nicolás Gallo (VAR) | P18: Group stage | Q18: 44897 | R18: 2–1 | S18: Facundo Tello | U18: Qatar | V18: 2022 | W18: Kim Young-gwon · 27|Hwang Hee-chan · 90+1 | X18: Ricardo Horta · 5 | Y18: ['27&rsquor;|1:1|Kim Young-gwon', '90+1&rsquor;|2:1|Hwang Hee-chan|Assist:|Son Heung-min'] | Z18: ['5&rsquor;|0:1|Ricardo Horta|Assist:|Diogo Dalot'] | AO18: ['36&rsquor;|1:1|Lee Kangin', '90+2&rsquor;|2:1|Hwang Hee-chan'] | AQ18: ['66&rsquor;|1:1|Hwang Hee-chan|for Lee Jae-sung', '81&rsquor;|1:1|Son Jun-ho|for Kim Young-gwon', '81&rsquor;|1:1|Hwang Ui-jo|for Lee Kangin', '90+3&rsquor;|2:1|Cho Yumin|for Cho Guesung'] | AR18: ['65&rsquor;|1:1|João Palhinha|for Matheus Nunes', '65&rsquor;|1:1|Rafael Leão|for Rúben Neves', '65&rsquor;|1:1|André Silva|for Cristiano Ronaldo', '82&rsquor;|1:1|Bernardo Silva|for João Mário', '82&rsquor;|1:1|William Carvalho|for Vitinha']
A19: Ghana | B19: Uruguay | C19: 0 | D19: 1.6 | F19: 2 | G19: 1.8 | I19: Otto Addo | J19: André Ayew | K19: Diego Alonso | L19: Luis Suárez | M19: 43443 | N19: Al Janoub Stadium, Al Wakrah | O19: Daniel Siebert (Referee) · Jan Seidel (AR1) · Rafael Foltyn (AR2) · Yoshimi Yamashita (4th) · Bastian Dankert (VAR) | P19: Group stage | Q19: 44897 | R19: 0–2 | S19: Daniel Siebert | U19: Qatar | V19: 2022 | X19: Giorgian De Arrascaeta · 26|Giorgian De Arrascaeta · 32 | Z19: ['26&rsquor;|0:1|Giorgian De Arrascaeta', '32&rsquor;|0:2|Giorgian De Arrascaeta|Assist:|Luis Suárez'] | AE19: ['21&rsquor;|0:0|André Ayew|Penalty saved by Sergio Rochet'] | AO19: ['86&rsquor;|0:2|Kamaldeen Sulemana', '90+9&rsquor;|0:2|Alidu Seidu'] | AP19: ['19&rsquor;|0:0|Darwin Núñez', '60&rsquor;|0:2|Luis Suárez', '87&rsquor;|0:2|Sebastián Coates', '90+10&rsquor;|0:2|Edinson Cavani', '90+10&rsquor;|0:2|José María Giménez'] | AQ19: ['46&rsquor;|0:2|Kamaldeen Sulemana|for Jordan Ayew', '46&rsquor;|0:2|Osman Bukari|for André Ayew', '72&rsquor;|0:2|Antoine Semenyo|for Daniel Amartey', '72&rsquor;|0:2|Daniel Kyereh|for Salis Abdul Samed', '90+8&rsquor;|0:2|Abdul Fatawu Issahaku|for Kudus Mohammed'] | AR19: ['34&rsquor;|0:2|Matías Vecino|for Rodrigo Bentancur', '66&rsquor;|0:2|Edinson Cavani|for Luis Suárez', '66&rsquor;|0:2|Nicolás De La Cruz|for Facundo Pellistri', '80&rsquor;|0:2|Maxi Gómez|for Darwin Núñez', '80&rsquor;|0:2|Agustín Canobbio|for Giorgian De Arrascaeta']
A20: Cameroon | B20: Brazil | C20: 1 | D20: 0.5 | F20: 0 | G20: 2.5 | I20: Rigobert Song | J20: Vincent Aboubakar | K20: Tite | L20: Dani Alves | M20: 85986 | N20: Lusail Iconic Stadium, Lusail | O20: Ismail Elfath (Referee) · Kyle Atkins (AR1) · Corey Parker (AR2) · Ma Ning (4th) · Alejandro Hernández (VAR) | P20: Group stage | Q20: 44897 | R20: 1–0 | S20: Ismail Elfath | U20: Qatar | V20: 2022 | W20: Vincent Aboubakar · 90+2 | Y20: ['90+2&rsquor;|1:0|Vincent Aboubakar|Assist:|Andre-Frank Zambo Anguissa'] | AM20: Vincent Aboubakar · 90+3 | AO20: ['6&rsquor;|0:0|Nouhou Tolo', '28&rsquor;|0:0|Pierre Kunde', '33&rsquor;|0:0|Collins Fai', '81&rsquor;|0:0|Vincent Aboubakar'] | AP20: ['7&rsquor;|0:0|Éder Militão', '85&rsquor;|0:0|Bruno Guimarães'] | AQ20: ['64&rsquor;|0:0|Karl Toko Ekambi|for Bryan Mbeumo', '66&rsquor;|0:0|Olivier Ntcham|for Pierre Kunde', '86&rsquor;|0:0|Jerome Ngom Mbekeli|for Moumi Ngamaleu'] | AR20: ['55&rsquor;|0:0|Everton Ribeiro|for Rodrygo', '55&rsquor;|0:0|Marquinhos|for Alex Telles', '55&rsquor;|0:0|Bruno Guimarães|for Fred', '64&rsquor;|0:0|Pedro|for Gabriel Jesus', '79&rsquor;|0:0|Raphinha|for Antony']
A21: Serbia | B21: Switzerland | C21: 2 | D21: 1.3 | F21: 3 | G21: 2.7 | I21: Dragan Stojković | J21: Dušan Tadić | K21: Murat Yakin | L21: Granit Xhaka | M21: 41378 | N21: Stadium 974, Doha | O21: Fernando Rapallini (Referee) · Juan Pablo Belatti (AR1) · Diego Bonfá (AR2) · Kevin Ortega (4th) · Mauro Vigliano (VAR) | P21: Group stage | Q21: 44897 | R21: 2–3 | S21: Fernando Rapallini | U21: Qatar | V21: 2022 | W21: Aleksandar Mitrović · 26|Dušan Vlahović · 35 | X21: Xherdan Shaqiri · 20|Breel Embolo · 44|Remo Freuler · 48 | Y21: ['26&rsquor;|1:1|Aleksandar Mitrović|Assist:|Dušan Tadić', '35&rsquor;|2:1|Dušan Vlahović'] | Z21: ['20&rsquor;|0:1|Xherdan Shaqiri|Assist:|Djibril Sow', '44&rsquor;|2:2|Breel Embolo|Assist:|Silvan Widmer', '48&rsquor;|2:3|Remo Freuler|Assist:|Ruben Vargas'] | AO21: ['47&rsquor;|2:2|Sergej Milinković-Savić', '56&rsquor;|2:3|Strahinja Pavlović', '66&rsquor;|2:3|Predrag Rajković', '81&rsquor;|2:3|Nemanja Gudelj', '82&rsquor;|2:3|Aleksandar Mitrović', '90+5&rsquor;|2:3|Nikola Milenković', '90+10&rsquor;|2:3|Saša Lukić'] | AP21: ['15&rsquor;|0:0|Silvan Widmer', '34&rsquor;|1:1|Ruben Vargas', '90+5&rsquor;|2:3|Granit Xhaka', '90+9&rsquor;|2:3|Fabian Schär'] | AQ21: ['55&rsquor;|2:3|Nemanja Gudelj|for Miloš Veljković', '55&rsquor;|2:3|Luka Jović|for Dušan Vlahović', '67&rsquor;|2:3|Nemanja Maksimović|for Sergej Milinković-Savić', '78&rsquor;|2:3|Filip Đuričić|for Dušan Tadić', '78&rsquor;|2:3|Nemanja Radonjić|for Andrija Živković'] | AR21: ['68&rsquor;|2:3|Edimilson Fernandes|for Djibril Sow', '69&rsquor;|2:3|Denis Zakaria|for Xherdan Shaqiri', '83&rsquor;|2:3|Christian Fassnacht|for Ruben Vargas', '90+6&rsquor;|2:3|Noah Okafor|for Breel Embolo']
